[2023-11-26T12:38:06.416+0000] {taskinstance.py:1159} INFO - Dependencies all met for dep_context=non-requeueable deps ti=<TaskInstance: dag_pg_insert.firs_task manual__2023-11-26T12:38:05.938797+00:00 [queued]>
[2023-11-26T12:38:06.430+0000] {taskinstance.py:1159} INFO - Dependencies all met for dep_context=requeueable deps ti=<TaskInstance: dag_pg_insert.firs_task manual__2023-11-26T12:38:05.938797+00:00 [queued]>
[2023-11-26T12:38:06.431+0000] {taskinstance.py:1361} INFO - Starting attempt 1 of 4
[2023-11-26T12:38:06.447+0000] {taskinstance.py:1382} INFO - Executing <Task(BashOperator): firs_task> on 2023-11-26 12:38:05.938797+00:00
[2023-11-26T12:38:06.453+0000] {standard_task_runner.py:57} INFO - Started process 1233 to run task
[2023-11-26T12:38:06.458+0000] {standard_task_runner.py:84} INFO - Running: ['***', 'tasks', 'run', 'dag_pg_insert', 'firs_task', 'manual__2023-11-26T12:38:05.938797+00:00', '--job-id', '1871', '--raw', '--subdir', 'DAGS_FOLDER/pg_insert_dag.py', '--cfg-path', '/tmp/tmptxf7kb18']
[2023-11-26T12:38:06.461+0000] {standard_task_runner.py:85} INFO - Job 1871: Subtask firs_task
[2023-11-26T12:38:06.522+0000] {task_command.py:416} INFO - Running <TaskInstance: dag_pg_insert.firs_task manual__2023-11-26T12:38:05.938797+00:00 [running]> on host 3498adef4c60
[2023-11-26T12:38:06.626+0000] {taskinstance.py:1662} INFO - Exporting env vars: AIRFLOW_CTX_DAG_EMAIL='butin_0404@mail.com' AIRFLOW_CTX_DAG_OWNER='big_data' AIRFLOW_CTX_DAG_ID='dag_pg_insert' AIRFLOW_CTX_TASK_ID='firs_task' AIRFLOW_CTX_EXECUTION_DATE='2023-11-26T12:38:05.938797+00:00' AIRFLOW_CTX_TRY_NUMBER='1' AIRFLOW_CTX_DAG_RUN_ID='manual__2023-11-26T12:38:05.938797+00:00'
[2023-11-26T12:38:06.628+0000] {subprocess.py:63} INFO - Tmp dir root location: /tmp
[2023-11-26T12:38:06.629+0000] {subprocess.py:75} INFO - Running command: ['/bin/bash', '-c', 'python3 /opt/***/dags/pg_read.py 127.0.0.1 *** *** 5432']
[2023-11-26T12:38:06.639+0000] {subprocess.py:86} INFO - Output:
[2023-11-26T12:38:08.162+0000] {subprocess.py:93} INFO - 127.0.0.1 *** *** 5432
[2023-11-26T12:38:08.173+0000] {subprocess.py:93} INFO - Traceback (most recent call last):
[2023-11-26T12:38:08.174+0000] {subprocess.py:93} INFO -   File "/home/***/.local/lib/python3.8/site-packages/sqlalchemy/engine/base.py", line 3371, in _wrap_pool_connect
[2023-11-26T12:38:08.175+0000] {subprocess.py:93} INFO -     return fn()
[2023-11-26T12:38:08.175+0000] {subprocess.py:93} INFO -   File "/home/***/.local/lib/python3.8/site-packages/sqlalchemy/pool/base.py", line 327, in connect
[2023-11-26T12:38:08.176+0000] {subprocess.py:93} INFO -     return _ConnectionFairy._checkout(self)
[2023-11-26T12:38:08.177+0000] {subprocess.py:93} INFO -   File "/home/***/.local/lib/python3.8/site-packages/sqlalchemy/pool/base.py", line 894, in _checkout
[2023-11-26T12:38:08.177+0000] {subprocess.py:93} INFO -     fairy = _ConnectionRecord.checkout(pool)
[2023-11-26T12:38:08.178+0000] {subprocess.py:93} INFO -   File "/home/***/.local/lib/python3.8/site-packages/sqlalchemy/pool/base.py", line 493, in checkout
[2023-11-26T12:38:08.178+0000] {subprocess.py:93} INFO -     rec = pool._do_get()
[2023-11-26T12:38:08.179+0000] {subprocess.py:93} INFO -   File "/home/***/.local/lib/python3.8/site-packages/sqlalchemy/pool/impl.py", line 146, in _do_get
[2023-11-26T12:38:08.179+0000] {subprocess.py:93} INFO -     self._dec_overflow()
[2023-11-26T12:38:08.180+0000] {subprocess.py:93} INFO -   File "/home/***/.local/lib/python3.8/site-packages/sqlalchemy/util/langhelpers.py", line 70, in __exit__
[2023-11-26T12:38:08.180+0000] {subprocess.py:93} INFO -     compat.raise_(
[2023-11-26T12:38:08.181+0000] {subprocess.py:93} INFO -   File "/home/***/.local/lib/python3.8/site-packages/sqlalchemy/util/compat.py", line 211, in raise_
[2023-11-26T12:38:08.181+0000] {subprocess.py:93} INFO -     raise exception
[2023-11-26T12:38:08.182+0000] {subprocess.py:93} INFO -   File "/home/***/.local/lib/python3.8/site-packages/sqlalchemy/pool/impl.py", line 143, in _do_get
[2023-11-26T12:38:08.183+0000] {subprocess.py:93} INFO -     return self._create_connection()
[2023-11-26T12:38:08.184+0000] {subprocess.py:93} INFO -   File "/home/***/.local/lib/python3.8/site-packages/sqlalchemy/pool/base.py", line 273, in _create_connection
[2023-11-26T12:38:08.184+0000] {subprocess.py:93} INFO -     return _ConnectionRecord(self)
[2023-11-26T12:38:08.185+0000] {subprocess.py:93} INFO -   File "/home/***/.local/lib/python3.8/site-packages/sqlalchemy/pool/base.py", line 388, in __init__
[2023-11-26T12:38:08.185+0000] {subprocess.py:93} INFO -     self.__connect()
[2023-11-26T12:38:08.186+0000] {subprocess.py:93} INFO -   File "/home/***/.local/lib/python3.8/site-packages/sqlalchemy/pool/base.py", line 691, in __connect
[2023-11-26T12:38:08.186+0000] {subprocess.py:93} INFO -     pool.logger.debug("Error on connect(): %s", e)
[2023-11-26T12:38:08.187+0000] {subprocess.py:93} INFO -   File "/home/***/.local/lib/python3.8/site-packages/sqlalchemy/util/langhelpers.py", line 70, in __exit__
[2023-11-26T12:38:08.188+0000] {subprocess.py:93} INFO -     compat.raise_(
[2023-11-26T12:38:08.189+0000] {subprocess.py:93} INFO -   File "/home/***/.local/lib/python3.8/site-packages/sqlalchemy/util/compat.py", line 211, in raise_
[2023-11-26T12:38:08.189+0000] {subprocess.py:93} INFO -     raise exception
[2023-11-26T12:38:08.190+0000] {subprocess.py:93} INFO -   File "/home/***/.local/lib/python3.8/site-packages/sqlalchemy/pool/base.py", line 686, in __connect
[2023-11-26T12:38:08.191+0000] {subprocess.py:93} INFO -     self.dbapi_connection = connection = pool._invoke_creator(self)
[2023-11-26T12:38:08.191+0000] {subprocess.py:93} INFO -   File "/home/***/.local/lib/python3.8/site-packages/sqlalchemy/engine/create.py", line 574, in connect
[2023-11-26T12:38:08.192+0000] {subprocess.py:93} INFO -     return dialect.connect(*cargs, **cparams)
[2023-11-26T12:38:08.192+0000] {subprocess.py:93} INFO -   File "/home/***/.local/lib/python3.8/site-packages/sqlalchemy/engine/default.py", line 598, in connect
[2023-11-26T12:38:08.193+0000] {subprocess.py:93} INFO -     return self.dbapi.connect(*cargs, **cparams)
[2023-11-26T12:38:08.193+0000] {subprocess.py:93} INFO -   File "/home/***/.local/lib/python3.8/site-packages/psycopg2/__init__.py", line 122, in connect
[2023-11-26T12:38:08.194+0000] {subprocess.py:93} INFO -     conn = _connect(dsn, connection_factory=connection_factory, **kwasync)
[2023-11-26T12:38:08.194+0000] {subprocess.py:93} INFO - psycopg2.OperationalError: connection to server at "127.0.0.1", port 5432 failed: Connection refused
[2023-11-26T12:38:08.195+0000] {subprocess.py:93} INFO - 	Is the server running on that host and accepting TCP/IP connections?
[2023-11-26T12:38:08.195+0000] {subprocess.py:93} INFO - 
[2023-11-26T12:38:08.196+0000] {subprocess.py:93} INFO - 
[2023-11-26T12:38:08.196+0000] {subprocess.py:93} INFO - The above exception was the direct cause of the following exception:
[2023-11-26T12:38:08.197+0000] {subprocess.py:93} INFO - 
[2023-11-26T12:38:08.197+0000] {subprocess.py:93} INFO - Traceback (most recent call last):
[2023-11-26T12:38:08.197+0000] {subprocess.py:93} INFO -   File "/opt/***/dags/pg_read.py", line 26, in <module>
[2023-11-26T12:38:08.198+0000] {subprocess.py:93} INFO -     df = pd.read_sql(sql, engine)
[2023-11-26T12:38:08.199+0000] {subprocess.py:93} INFO -   File "/home/***/.local/lib/python3.8/site-packages/pandas/io/sql.py", line 633, in read_sql
[2023-11-26T12:38:08.199+0000] {subprocess.py:93} INFO -     with pandasSQL_builder(con) as pandas_sql:
[2023-11-26T12:38:08.199+0000] {subprocess.py:93} INFO -   File "/home/***/.local/lib/python3.8/site-packages/pandas/io/sql.py", line 832, in pandasSQL_builder
[2023-11-26T12:38:08.200+0000] {subprocess.py:93} INFO -     return SQLDatabase(con, schema, need_transaction)
[2023-11-26T12:38:08.200+0000] {subprocess.py:93} INFO -   File "/home/***/.local/lib/python3.8/site-packages/pandas/io/sql.py", line 1539, in __init__
[2023-11-26T12:38:08.201+0000] {subprocess.py:93} INFO -     con = self.exit_stack.enter_context(con.connect())
[2023-11-26T12:38:08.201+0000] {subprocess.py:93} INFO -   File "/home/***/.local/lib/python3.8/site-packages/sqlalchemy/engine/base.py", line 3325, in connect
[2023-11-26T12:38:08.202+0000] {subprocess.py:93} INFO -     return self._connection_cls(self, close_with_result=close_with_result)
[2023-11-26T12:38:08.202+0000] {subprocess.py:93} INFO -   File "/home/***/.local/lib/python3.8/site-packages/sqlalchemy/engine/base.py", line 96, in __init__
[2023-11-26T12:38:08.203+0000] {subprocess.py:93} INFO -     else engine.raw_connection()
[2023-11-26T12:38:08.203+0000] {subprocess.py:93} INFO -   File "/home/***/.local/lib/python3.8/site-packages/sqlalchemy/engine/base.py", line 3404, in raw_connection
[2023-11-26T12:38:08.203+0000] {subprocess.py:93} INFO -     return self._wrap_pool_connect(self.pool.connect, _connection)
[2023-11-26T12:38:08.204+0000] {subprocess.py:93} INFO -   File "/home/***/.local/lib/python3.8/site-packages/sqlalchemy/engine/base.py", line 3374, in _wrap_pool_connect
[2023-11-26T12:38:08.204+0000] {subprocess.py:93} INFO -     Connection._handle_dbapi_exception_noconnection(
[2023-11-26T12:38:08.204+0000] {subprocess.py:93} INFO -   File "/home/***/.local/lib/python3.8/site-packages/sqlalchemy/engine/base.py", line 2208, in _handle_dbapi_exception_noconnection
[2023-11-26T12:38:08.205+0000] {subprocess.py:93} INFO -     util.raise_(
[2023-11-26T12:38:08.205+0000] {subprocess.py:93} INFO -   File "/home/***/.local/lib/python3.8/site-packages/sqlalchemy/util/compat.py", line 211, in raise_
[2023-11-26T12:38:08.205+0000] {subprocess.py:93} INFO -     raise exception
[2023-11-26T12:38:08.206+0000] {subprocess.py:93} INFO -   File "/home/***/.local/lib/python3.8/site-packages/sqlalchemy/engine/base.py", line 3371, in _wrap_pool_connect
[2023-11-26T12:38:08.206+0000] {subprocess.py:93} INFO -     return fn()
[2023-11-26T12:38:08.206+0000] {subprocess.py:93} INFO -   File "/home/***/.local/lib/python3.8/site-packages/sqlalchemy/pool/base.py", line 327, in connect
[2023-11-26T12:38:08.207+0000] {subprocess.py:93} INFO -     return _ConnectionFairy._checkout(self)
[2023-11-26T12:38:08.207+0000] {subprocess.py:93} INFO -   File "/home/***/.local/lib/python3.8/site-packages/sqlalchemy/pool/base.py", line 894, in _checkout
[2023-11-26T12:38:08.207+0000] {subprocess.py:93} INFO -     fairy = _ConnectionRecord.checkout(pool)
[2023-11-26T12:38:08.208+0000] {subprocess.py:93} INFO -   File "/home/***/.local/lib/python3.8/site-packages/sqlalchemy/pool/base.py", line 493, in checkout
[2023-11-26T12:38:08.208+0000] {subprocess.py:93} INFO -     rec = pool._do_get()
[2023-11-26T12:38:08.208+0000] {subprocess.py:93} INFO -   File "/home/***/.local/lib/python3.8/site-packages/sqlalchemy/pool/impl.py", line 146, in _do_get
[2023-11-26T12:38:08.209+0000] {subprocess.py:93} INFO -     self._dec_overflow()
[2023-11-26T12:38:08.209+0000] {subprocess.py:93} INFO -   File "/home/***/.local/lib/python3.8/site-packages/sqlalchemy/util/langhelpers.py", line 70, in __exit__
[2023-11-26T12:38:08.209+0000] {subprocess.py:93} INFO -     compat.raise_(
[2023-11-26T12:38:08.210+0000] {subprocess.py:93} INFO -   File "/home/***/.local/lib/python3.8/site-packages/sqlalchemy/util/compat.py", line 211, in raise_
[2023-11-26T12:38:08.210+0000] {subprocess.py:93} INFO -     raise exception
[2023-11-26T12:38:08.210+0000] {subprocess.py:93} INFO -   File "/home/***/.local/lib/python3.8/site-packages/sqlalchemy/pool/impl.py", line 143, in _do_get
[2023-11-26T12:38:08.211+0000] {subprocess.py:93} INFO -     return self._create_connection()
[2023-11-26T12:38:08.211+0000] {subprocess.py:93} INFO -   File "/home/***/.local/lib/python3.8/site-packages/sqlalchemy/pool/base.py", line 273, in _create_connection
[2023-11-26T12:38:08.211+0000] {subprocess.py:93} INFO -     return _ConnectionRecord(self)
[2023-11-26T12:38:08.211+0000] {subprocess.py:93} INFO -   File "/home/***/.local/lib/python3.8/site-packages/sqlalchemy/pool/base.py", line 388, in __init__
[2023-11-26T12:38:08.212+0000] {subprocess.py:93} INFO -     self.__connect()
[2023-11-26T12:38:08.212+0000] {subprocess.py:93} INFO -   File "/home/***/.local/lib/python3.8/site-packages/sqlalchemy/pool/base.py", line 691, in __connect
[2023-11-26T12:38:08.212+0000] {subprocess.py:93} INFO -     pool.logger.debug("Error on connect(): %s", e)
[2023-11-26T12:38:08.213+0000] {subprocess.py:93} INFO -   File "/home/***/.local/lib/python3.8/site-packages/sqlalchemy/util/langhelpers.py", line 70, in __exit__
[2023-11-26T12:38:08.213+0000] {subprocess.py:93} INFO -     compat.raise_(
[2023-11-26T12:38:08.214+0000] {subprocess.py:93} INFO -   File "/home/***/.local/lib/python3.8/site-packages/sqlalchemy/util/compat.py", line 211, in raise_
[2023-11-26T12:38:08.215+0000] {subprocess.py:93} INFO -     raise exception
[2023-11-26T12:38:08.216+0000] {subprocess.py:93} INFO -   File "/home/***/.local/lib/python3.8/site-packages/sqlalchemy/pool/base.py", line 686, in __connect
[2023-11-26T12:38:08.217+0000] {subprocess.py:93} INFO -     self.dbapi_connection = connection = pool._invoke_creator(self)
[2023-11-26T12:38:08.218+0000] {subprocess.py:93} INFO -   File "/home/***/.local/lib/python3.8/site-packages/sqlalchemy/engine/create.py", line 574, in connect
[2023-11-26T12:38:08.219+0000] {subprocess.py:93} INFO -     return dialect.connect(*cargs, **cparams)
[2023-11-26T12:38:08.219+0000] {subprocess.py:93} INFO -   File "/home/***/.local/lib/python3.8/site-packages/sqlalchemy/engine/default.py", line 598, in connect
[2023-11-26T12:38:08.220+0000] {subprocess.py:93} INFO -     return self.dbapi.connect(*cargs, **cparams)
[2023-11-26T12:38:08.220+0000] {subprocess.py:93} INFO -   File "/home/***/.local/lib/python3.8/site-packages/psycopg2/__init__.py", line 122, in connect
[2023-11-26T12:38:08.221+0000] {subprocess.py:93} INFO -     conn = _connect(dsn, connection_factory=connection_factory, **kwasync)
[2023-11-26T12:38:08.221+0000] {subprocess.py:93} INFO - sqlalchemy.exc.OperationalError: (psycopg2.OperationalError) connection to server at "127.0.0.1", port 5432 failed: Connection refused
[2023-11-26T12:38:08.222+0000] {subprocess.py:93} INFO - 	Is the server running on that host and accepting TCP/IP connections?
[2023-11-26T12:38:08.222+0000] {subprocess.py:93} INFO - 
[2023-11-26T12:38:08.223+0000] {subprocess.py:93} INFO - (Background on this error at: https://sqlalche.me/e/14/e3q8)
[2023-11-26T12:38:08.292+0000] {subprocess.py:97} INFO - Command exited with return code 1
[2023-11-26T12:38:08.308+0000] {taskinstance.py:1937} ERROR - Task failed with exception
Traceback (most recent call last):
  File "/home/airflow/.local/lib/python3.8/site-packages/airflow/operators/bash.py", line 210, in execute
    raise AirflowException(
airflow.exceptions.AirflowException: Bash command failed. The command returned a non-zero exit code 1.
[2023-11-26T12:38:08.313+0000] {taskinstance.py:1400} INFO - Marking task as UP_FOR_RETRY. dag_id=dag_pg_insert, task_id=firs_task, execution_date=20231126T123805, start_date=20231126T123806, end_date=20231126T123808
[2023-11-26T12:38:08.383+0000] {standard_task_runner.py:104} ERROR - Failed to execute job 1871 for task firs_task (Bash command failed. The command returned a non-zero exit code 1.; 1233)
[2023-11-26T12:38:08.400+0000] {local_task_job_runner.py:228} INFO - Task exited with return code 1
[2023-11-26T12:38:08.437+0000] {taskinstance.py:2778} INFO - 0 downstream tasks scheduled from follow-on schedule check
