[2023-11-23T00:51:09.823+0000] {processor.py:157} INFO - Started process (PID=790) to work on /opt/airflow/dags/pg_read_dag.py
[2023-11-23T00:51:09.825+0000] {processor.py:829} INFO - Processing file /opt/airflow/dags/pg_read_dag.py for tasks to queue
[2023-11-23T00:51:09.826+0000] {logging_mixin.py:151} INFO - [2023-11-23T00:51:09.826+0000] {dagbag.py:536} INFO - Filling up the DagBag from /opt/airflow/dags/pg_read_dag.py
[2023-11-23T00:51:09.894+0000] {logging_mixin.py:151} INFO - [2023-11-23T00:51:09.883+0000] {dagbag.py:346} ERROR - Failed to import: /opt/airflow/dags/pg_read_dag.py
Traceback (most recent call last):
  File "/home/airflow/.local/lib/python3.8/site-packages/airflow/models/dagbag.py", line 342, in parse
    loader.exec_module(new_module)
  File "<frozen importlib._bootstrap_external>", line 843, in exec_module
  File "<frozen importlib._bootstrap>", line 219, in _call_with_frames_removed
  File "/opt/airflow/dags/pg_read_dag.py", line 7, in <module>
    postgre_con = BaseHook.get_connection('postgre_sql_conn')
  File "/home/airflow/.local/lib/python3.8/site-packages/airflow/hooks/base.py", line 72, in get_connection
    conn = Connection.get_connection_from_secrets(conn_id)
  File "/home/airflow/.local/lib/python3.8/site-packages/airflow/models/connection.py", line 477, in get_connection_from_secrets
    raise AirflowNotFoundException(f"The conn_id `{conn_id}` isn't defined")
airflow.exceptions.AirflowNotFoundException: The conn_id `postgre_sql_conn` isn't defined
[2023-11-23T00:51:09.895+0000] {processor.py:841} WARNING - No viable dags retrieved from /opt/airflow/dags/pg_read_dag.py
[2023-11-23T00:51:09.911+0000] {processor.py:179} INFO - Processing /opt/airflow/dags/pg_read_dag.py took 0.091 seconds
[2023-11-23T00:51:40.286+0000] {processor.py:157} INFO - Started process (PID=807) to work on /opt/airflow/dags/pg_read_dag.py
[2023-11-23T00:51:40.288+0000] {processor.py:829} INFO - Processing file /opt/airflow/dags/pg_read_dag.py for tasks to queue
[2023-11-23T00:51:40.289+0000] {logging_mixin.py:151} INFO - [2023-11-23T00:51:40.289+0000] {dagbag.py:536} INFO - Filling up the DagBag from /opt/airflow/dags/pg_read_dag.py
[2023-11-23T00:51:40.344+0000] {logging_mixin.py:151} INFO - [2023-11-23T00:51:40.333+0000] {dagbag.py:346} ERROR - Failed to import: /opt/airflow/dags/pg_read_dag.py
Traceback (most recent call last):
  File "/home/airflow/.local/lib/python3.8/site-packages/airflow/models/dagbag.py", line 342, in parse
    loader.exec_module(new_module)
  File "<frozen importlib._bootstrap_external>", line 843, in exec_module
  File "<frozen importlib._bootstrap>", line 219, in _call_with_frames_removed
  File "/opt/airflow/dags/pg_read_dag.py", line 7, in <module>
    postgre_con = BaseHook.get_connection('postgre_sql_conn')
  File "/home/airflow/.local/lib/python3.8/site-packages/airflow/hooks/base.py", line 72, in get_connection
    conn = Connection.get_connection_from_secrets(conn_id)
  File "/home/airflow/.local/lib/python3.8/site-packages/airflow/models/connection.py", line 477, in get_connection_from_secrets
    raise AirflowNotFoundException(f"The conn_id `{conn_id}` isn't defined")
airflow.exceptions.AirflowNotFoundException: The conn_id `postgre_sql_conn` isn't defined
[2023-11-23T00:51:40.345+0000] {processor.py:841} WARNING - No viable dags retrieved from /opt/airflow/dags/pg_read_dag.py
[2023-11-23T00:51:40.396+0000] {processor.py:179} INFO - Processing /opt/airflow/dags/pg_read_dag.py took 0.116 seconds
[2023-11-23T00:52:10.625+0000] {processor.py:157} INFO - Started process (PID=824) to work on /opt/airflow/dags/pg_read_dag.py
[2023-11-23T00:52:10.626+0000] {processor.py:829} INFO - Processing file /opt/airflow/dags/pg_read_dag.py for tasks to queue
[2023-11-23T00:52:10.628+0000] {logging_mixin.py:151} INFO - [2023-11-23T00:52:10.627+0000] {dagbag.py:536} INFO - Filling up the DagBag from /opt/airflow/dags/pg_read_dag.py
[2023-11-23T00:52:10.670+0000] {logging_mixin.py:151} INFO - [2023-11-23T00:52:10.663+0000] {dagbag.py:346} ERROR - Failed to import: /opt/airflow/dags/pg_read_dag.py
Traceback (most recent call last):
  File "/home/airflow/.local/lib/python3.8/site-packages/airflow/models/dagbag.py", line 342, in parse
    loader.exec_module(new_module)
  File "<frozen importlib._bootstrap_external>", line 843, in exec_module
  File "<frozen importlib._bootstrap>", line 219, in _call_with_frames_removed
  File "/opt/airflow/dags/pg_read_dag.py", line 7, in <module>
    postgre_con = BaseHook.get_connection('postgre_sql_conn')
  File "/home/airflow/.local/lib/python3.8/site-packages/airflow/hooks/base.py", line 72, in get_connection
    conn = Connection.get_connection_from_secrets(conn_id)
  File "/home/airflow/.local/lib/python3.8/site-packages/airflow/models/connection.py", line 477, in get_connection_from_secrets
    raise AirflowNotFoundException(f"The conn_id `{conn_id}` isn't defined")
airflow.exceptions.AirflowNotFoundException: The conn_id `postgre_sql_conn` isn't defined
[2023-11-23T00:52:10.670+0000] {processor.py:841} WARNING - No viable dags retrieved from /opt/airflow/dags/pg_read_dag.py
[2023-11-23T00:52:10.684+0000] {processor.py:179} INFO - Processing /opt/airflow/dags/pg_read_dag.py took 0.063 seconds
[2023-11-23T00:52:41.166+0000] {processor.py:157} INFO - Started process (PID=841) to work on /opt/airflow/dags/pg_read_dag.py
[2023-11-23T00:52:41.168+0000] {processor.py:829} INFO - Processing file /opt/airflow/dags/pg_read_dag.py for tasks to queue
[2023-11-23T00:52:41.169+0000] {logging_mixin.py:151} INFO - [2023-11-23T00:52:41.168+0000] {dagbag.py:536} INFO - Filling up the DagBag from /opt/airflow/dags/pg_read_dag.py
[2023-11-23T00:52:41.269+0000] {logging_mixin.py:151} INFO - [2023-11-23T00:52:41.265+0000] {dagbag.py:346} ERROR - Failed to import: /opt/airflow/dags/pg_read_dag.py
Traceback (most recent call last):
  File "/home/airflow/.local/lib/python3.8/site-packages/airflow/models/dagbag.py", line 342, in parse
    loader.exec_module(new_module)
  File "<frozen importlib._bootstrap_external>", line 843, in exec_module
  File "<frozen importlib._bootstrap>", line 219, in _call_with_frames_removed
  File "/opt/airflow/dags/pg_read_dag.py", line 7, in <module>
    postgre_con = BaseHook.get_connection('postgre_sql_conn')
  File "/home/airflow/.local/lib/python3.8/site-packages/airflow/hooks/base.py", line 72, in get_connection
    conn = Connection.get_connection_from_secrets(conn_id)
  File "/home/airflow/.local/lib/python3.8/site-packages/airflow/models/connection.py", line 477, in get_connection_from_secrets
    raise AirflowNotFoundException(f"The conn_id `{conn_id}` isn't defined")
airflow.exceptions.AirflowNotFoundException: The conn_id `postgre_sql_conn` isn't defined
[2023-11-23T00:52:41.270+0000] {processor.py:841} WARNING - No viable dags retrieved from /opt/airflow/dags/pg_read_dag.py
[2023-11-23T00:52:41.283+0000] {processor.py:179} INFO - Processing /opt/airflow/dags/pg_read_dag.py took 0.122 seconds
[2023-11-23T00:53:11.781+0000] {processor.py:157} INFO - Started process (PID=858) to work on /opt/airflow/dags/pg_read_dag.py
[2023-11-23T00:53:11.783+0000] {processor.py:829} INFO - Processing file /opt/airflow/dags/pg_read_dag.py for tasks to queue
[2023-11-23T00:53:11.785+0000] {logging_mixin.py:151} INFO - [2023-11-23T00:53:11.784+0000] {dagbag.py:536} INFO - Filling up the DagBag from /opt/airflow/dags/pg_read_dag.py
[2023-11-23T00:53:11.846+0000] {logging_mixin.py:151} INFO - [2023-11-23T00:53:11.839+0000] {dagbag.py:346} ERROR - Failed to import: /opt/airflow/dags/pg_read_dag.py
Traceback (most recent call last):
  File "/home/airflow/.local/lib/python3.8/site-packages/airflow/models/dagbag.py", line 342, in parse
    loader.exec_module(new_module)
  File "<frozen importlib._bootstrap_external>", line 843, in exec_module
  File "<frozen importlib._bootstrap>", line 219, in _call_with_frames_removed
  File "/opt/airflow/dags/pg_read_dag.py", line 7, in <module>
    postgre_con = BaseHook.get_connection('postgre_sql_conn')
  File "/home/airflow/.local/lib/python3.8/site-packages/airflow/hooks/base.py", line 72, in get_connection
    conn = Connection.get_connection_from_secrets(conn_id)
  File "/home/airflow/.local/lib/python3.8/site-packages/airflow/models/connection.py", line 477, in get_connection_from_secrets
    raise AirflowNotFoundException(f"The conn_id `{conn_id}` isn't defined")
airflow.exceptions.AirflowNotFoundException: The conn_id `postgre_sql_conn` isn't defined
[2023-11-23T00:53:11.847+0000] {processor.py:841} WARNING - No viable dags retrieved from /opt/airflow/dags/pg_read_dag.py
[2023-11-23T00:53:11.895+0000] {processor.py:179} INFO - Processing /opt/airflow/dags/pg_read_dag.py took 0.119 seconds
[2023-11-23T00:53:42.215+0000] {processor.py:157} INFO - Started process (PID=875) to work on /opt/airflow/dags/pg_read_dag.py
[2023-11-23T00:53:42.216+0000] {processor.py:829} INFO - Processing file /opt/airflow/dags/pg_read_dag.py for tasks to queue
[2023-11-23T00:53:42.217+0000] {logging_mixin.py:151} INFO - [2023-11-23T00:53:42.217+0000] {dagbag.py:536} INFO - Filling up the DagBag from /opt/airflow/dags/pg_read_dag.py
[2023-11-23T00:53:42.260+0000] {logging_mixin.py:151} INFO - [2023-11-23T00:53:42.250+0000] {dagbag.py:346} ERROR - Failed to import: /opt/airflow/dags/pg_read_dag.py
Traceback (most recent call last):
  File "/home/airflow/.local/lib/python3.8/site-packages/airflow/models/dagbag.py", line 342, in parse
    loader.exec_module(new_module)
  File "<frozen importlib._bootstrap_external>", line 843, in exec_module
  File "<frozen importlib._bootstrap>", line 219, in _call_with_frames_removed
  File "/opt/airflow/dags/pg_read_dag.py", line 7, in <module>
    postgre_con = BaseHook.get_connection('postgre_sql_conn')
  File "/home/airflow/.local/lib/python3.8/site-packages/airflow/hooks/base.py", line 72, in get_connection
    conn = Connection.get_connection_from_secrets(conn_id)
  File "/home/airflow/.local/lib/python3.8/site-packages/airflow/models/connection.py", line 477, in get_connection_from_secrets
    raise AirflowNotFoundException(f"The conn_id `{conn_id}` isn't defined")
airflow.exceptions.AirflowNotFoundException: The conn_id `postgre_sql_conn` isn't defined
[2023-11-23T00:53:42.261+0000] {processor.py:841} WARNING - No viable dags retrieved from /opt/airflow/dags/pg_read_dag.py
[2023-11-23T00:53:42.299+0000] {processor.py:179} INFO - Processing /opt/airflow/dags/pg_read_dag.py took 0.089 seconds
[2023-11-23T00:54:12.730+0000] {processor.py:157} INFO - Started process (PID=892) to work on /opt/airflow/dags/pg_read_dag.py
[2023-11-23T00:54:12.731+0000] {processor.py:829} INFO - Processing file /opt/airflow/dags/pg_read_dag.py for tasks to queue
[2023-11-23T00:54:12.733+0000] {logging_mixin.py:151} INFO - [2023-11-23T00:54:12.732+0000] {dagbag.py:536} INFO - Filling up the DagBag from /opt/airflow/dags/pg_read_dag.py
[2023-11-23T00:54:12.778+0000] {logging_mixin.py:151} INFO - [2023-11-23T00:54:12.771+0000] {dagbag.py:346} ERROR - Failed to import: /opt/airflow/dags/pg_read_dag.py
Traceback (most recent call last):
  File "/home/airflow/.local/lib/python3.8/site-packages/airflow/models/dagbag.py", line 342, in parse
    loader.exec_module(new_module)
  File "<frozen importlib._bootstrap_external>", line 843, in exec_module
  File "<frozen importlib._bootstrap>", line 219, in _call_with_frames_removed
  File "/opt/airflow/dags/pg_read_dag.py", line 7, in <module>
    postgre_con = BaseHook.get_connection('postgre_sql_conn')
  File "/home/airflow/.local/lib/python3.8/site-packages/airflow/hooks/base.py", line 72, in get_connection
    conn = Connection.get_connection_from_secrets(conn_id)
  File "/home/airflow/.local/lib/python3.8/site-packages/airflow/models/connection.py", line 477, in get_connection_from_secrets
    raise AirflowNotFoundException(f"The conn_id `{conn_id}` isn't defined")
airflow.exceptions.AirflowNotFoundException: The conn_id `postgre_sql_conn` isn't defined
[2023-11-23T00:54:12.779+0000] {processor.py:841} WARNING - No viable dags retrieved from /opt/airflow/dags/pg_read_dag.py
[2023-11-23T00:54:12.794+0000] {processor.py:179} INFO - Processing /opt/airflow/dags/pg_read_dag.py took 0.069 seconds
[2023-11-23T00:54:43.155+0000] {processor.py:157} INFO - Started process (PID=909) to work on /opt/airflow/dags/pg_read_dag.py
[2023-11-23T00:54:43.156+0000] {processor.py:829} INFO - Processing file /opt/airflow/dags/pg_read_dag.py for tasks to queue
[2023-11-23T00:54:43.156+0000] {logging_mixin.py:151} INFO - [2023-11-23T00:54:43.156+0000] {dagbag.py:536} INFO - Filling up the DagBag from /opt/airflow/dags/pg_read_dag.py
[2023-11-23T00:54:43.193+0000] {logging_mixin.py:151} INFO - [2023-11-23T00:54:43.185+0000] {dagbag.py:346} ERROR - Failed to import: /opt/airflow/dags/pg_read_dag.py
Traceback (most recent call last):
  File "/home/airflow/.local/lib/python3.8/site-packages/airflow/models/dagbag.py", line 342, in parse
    loader.exec_module(new_module)
  File "<frozen importlib._bootstrap_external>", line 843, in exec_module
  File "<frozen importlib._bootstrap>", line 219, in _call_with_frames_removed
  File "/opt/airflow/dags/pg_read_dag.py", line 7, in <module>
    postgre_con = BaseHook.get_connection('postgre_sql_conn')
  File "/home/airflow/.local/lib/python3.8/site-packages/airflow/hooks/base.py", line 72, in get_connection
    conn = Connection.get_connection_from_secrets(conn_id)
  File "/home/airflow/.local/lib/python3.8/site-packages/airflow/models/connection.py", line 477, in get_connection_from_secrets
    raise AirflowNotFoundException(f"The conn_id `{conn_id}` isn't defined")
airflow.exceptions.AirflowNotFoundException: The conn_id `postgre_sql_conn` isn't defined
[2023-11-23T00:54:43.194+0000] {processor.py:841} WARNING - No viable dags retrieved from /opt/airflow/dags/pg_read_dag.py
[2023-11-23T00:54:43.207+0000] {processor.py:179} INFO - Processing /opt/airflow/dags/pg_read_dag.py took 0.055 seconds
[2023-11-23T00:55:13.675+0000] {processor.py:157} INFO - Started process (PID=926) to work on /opt/airflow/dags/pg_read_dag.py
[2023-11-23T00:55:13.677+0000] {processor.py:829} INFO - Processing file /opt/airflow/dags/pg_read_dag.py for tasks to queue
[2023-11-23T00:55:13.680+0000] {logging_mixin.py:151} INFO - [2023-11-23T00:55:13.679+0000] {dagbag.py:536} INFO - Filling up the DagBag from /opt/airflow/dags/pg_read_dag.py
[2023-11-23T00:55:13.736+0000] {logging_mixin.py:151} INFO - [2023-11-23T00:55:13.728+0000] {dagbag.py:346} ERROR - Failed to import: /opt/airflow/dags/pg_read_dag.py
Traceback (most recent call last):
  File "/home/airflow/.local/lib/python3.8/site-packages/airflow/models/dagbag.py", line 342, in parse
    loader.exec_module(new_module)
  File "<frozen importlib._bootstrap_external>", line 843, in exec_module
  File "<frozen importlib._bootstrap>", line 219, in _call_with_frames_removed
  File "/opt/airflow/dags/pg_read_dag.py", line 7, in <module>
    postgre_con = BaseHook.get_connection('postgre_sql_conn')
  File "/home/airflow/.local/lib/python3.8/site-packages/airflow/hooks/base.py", line 72, in get_connection
    conn = Connection.get_connection_from_secrets(conn_id)
  File "/home/airflow/.local/lib/python3.8/site-packages/airflow/models/connection.py", line 477, in get_connection_from_secrets
    raise AirflowNotFoundException(f"The conn_id `{conn_id}` isn't defined")
airflow.exceptions.AirflowNotFoundException: The conn_id `postgre_sql_conn` isn't defined
[2023-11-23T00:55:13.738+0000] {processor.py:841} WARNING - No viable dags retrieved from /opt/airflow/dags/pg_read_dag.py
[2023-11-23T00:55:13.780+0000] {processor.py:179} INFO - Processing /opt/airflow/dags/pg_read_dag.py took 0.112 seconds
[2023-11-23T00:55:44.160+0000] {processor.py:157} INFO - Started process (PID=943) to work on /opt/airflow/dags/pg_read_dag.py
[2023-11-23T00:55:44.162+0000] {processor.py:829} INFO - Processing file /opt/airflow/dags/pg_read_dag.py for tasks to queue
[2023-11-23T00:55:44.165+0000] {logging_mixin.py:151} INFO - [2023-11-23T00:55:44.164+0000] {dagbag.py:536} INFO - Filling up the DagBag from /opt/airflow/dags/pg_read_dag.py
[2023-11-23T00:55:44.214+0000] {logging_mixin.py:151} INFO - [2023-11-23T00:55:44.206+0000] {dagbag.py:346} ERROR - Failed to import: /opt/airflow/dags/pg_read_dag.py
Traceback (most recent call last):
  File "/home/airflow/.local/lib/python3.8/site-packages/airflow/models/dagbag.py", line 342, in parse
    loader.exec_module(new_module)
  File "<frozen importlib._bootstrap_external>", line 843, in exec_module
  File "<frozen importlib._bootstrap>", line 219, in _call_with_frames_removed
  File "/opt/airflow/dags/pg_read_dag.py", line 7, in <module>
    postgre_con = BaseHook.get_connection('postgre_sql_conn')
  File "/home/airflow/.local/lib/python3.8/site-packages/airflow/hooks/base.py", line 72, in get_connection
    conn = Connection.get_connection_from_secrets(conn_id)
  File "/home/airflow/.local/lib/python3.8/site-packages/airflow/models/connection.py", line 477, in get_connection_from_secrets
    raise AirflowNotFoundException(f"The conn_id `{conn_id}` isn't defined")
airflow.exceptions.AirflowNotFoundException: The conn_id `postgre_sql_conn` isn't defined
[2023-11-23T00:55:44.215+0000] {processor.py:841} WARNING - No viable dags retrieved from /opt/airflow/dags/pg_read_dag.py
[2023-11-23T00:55:44.258+0000] {processor.py:179} INFO - Processing /opt/airflow/dags/pg_read_dag.py took 0.103 seconds
[2023-11-23T00:56:14.712+0000] {processor.py:157} INFO - Started process (PID=960) to work on /opt/airflow/dags/pg_read_dag.py
[2023-11-23T00:56:14.714+0000] {processor.py:829} INFO - Processing file /opt/airflow/dags/pg_read_dag.py for tasks to queue
[2023-11-23T00:56:14.716+0000] {logging_mixin.py:151} INFO - [2023-11-23T00:56:14.715+0000] {dagbag.py:536} INFO - Filling up the DagBag from /opt/airflow/dags/pg_read_dag.py
[2023-11-23T00:56:14.764+0000] {logging_mixin.py:151} INFO - [2023-11-23T00:56:14.758+0000] {dagbag.py:346} ERROR - Failed to import: /opt/airflow/dags/pg_read_dag.py
Traceback (most recent call last):
  File "/home/airflow/.local/lib/python3.8/site-packages/airflow/models/dagbag.py", line 342, in parse
    loader.exec_module(new_module)
  File "<frozen importlib._bootstrap_external>", line 843, in exec_module
  File "<frozen importlib._bootstrap>", line 219, in _call_with_frames_removed
  File "/opt/airflow/dags/pg_read_dag.py", line 7, in <module>
    postgre_con = BaseHook.get_connection('postgre_sql_conn')
  File "/home/airflow/.local/lib/python3.8/site-packages/airflow/hooks/base.py", line 72, in get_connection
    conn = Connection.get_connection_from_secrets(conn_id)
  File "/home/airflow/.local/lib/python3.8/site-packages/airflow/models/connection.py", line 477, in get_connection_from_secrets
    raise AirflowNotFoundException(f"The conn_id `{conn_id}` isn't defined")
airflow.exceptions.AirflowNotFoundException: The conn_id `postgre_sql_conn` isn't defined
[2023-11-23T00:56:14.765+0000] {processor.py:841} WARNING - No viable dags retrieved from /opt/airflow/dags/pg_read_dag.py
[2023-11-23T00:56:14.775+0000] {processor.py:179} INFO - Processing /opt/airflow/dags/pg_read_dag.py took 0.069 seconds
[2023-11-23T00:56:45.204+0000] {processor.py:157} INFO - Started process (PID=977) to work on /opt/airflow/dags/pg_read_dag.py
[2023-11-23T00:56:45.206+0000] {processor.py:829} INFO - Processing file /opt/airflow/dags/pg_read_dag.py for tasks to queue
[2023-11-23T00:56:45.208+0000] {logging_mixin.py:151} INFO - [2023-11-23T00:56:45.207+0000] {dagbag.py:536} INFO - Filling up the DagBag from /opt/airflow/dags/pg_read_dag.py
[2023-11-23T00:56:45.255+0000] {logging_mixin.py:151} INFO - [2023-11-23T00:56:45.247+0000] {dagbag.py:346} ERROR - Failed to import: /opt/airflow/dags/pg_read_dag.py
Traceback (most recent call last):
  File "/home/airflow/.local/lib/python3.8/site-packages/airflow/models/dagbag.py", line 342, in parse
    loader.exec_module(new_module)
  File "<frozen importlib._bootstrap_external>", line 843, in exec_module
  File "<frozen importlib._bootstrap>", line 219, in _call_with_frames_removed
  File "/opt/airflow/dags/pg_read_dag.py", line 7, in <module>
    postgre_con = BaseHook.get_connection('postgre_sql_conn')
  File "/home/airflow/.local/lib/python3.8/site-packages/airflow/hooks/base.py", line 72, in get_connection
    conn = Connection.get_connection_from_secrets(conn_id)
  File "/home/airflow/.local/lib/python3.8/site-packages/airflow/models/connection.py", line 477, in get_connection_from_secrets
    raise AirflowNotFoundException(f"The conn_id `{conn_id}` isn't defined")
airflow.exceptions.AirflowNotFoundException: The conn_id `postgre_sql_conn` isn't defined
[2023-11-23T00:56:45.256+0000] {processor.py:841} WARNING - No viable dags retrieved from /opt/airflow/dags/pg_read_dag.py
[2023-11-23T00:56:45.300+0000] {processor.py:179} INFO - Processing /opt/airflow/dags/pg_read_dag.py took 0.101 seconds
[2023-11-23T00:57:15.616+0000] {processor.py:157} INFO - Started process (PID=1001) to work on /opt/airflow/dags/pg_read_dag.py
[2023-11-23T00:57:15.618+0000] {processor.py:829} INFO - Processing file /opt/airflow/dags/pg_read_dag.py for tasks to queue
[2023-11-23T00:57:15.619+0000] {logging_mixin.py:151} INFO - [2023-11-23T00:57:15.619+0000] {dagbag.py:536} INFO - Filling up the DagBag from /opt/airflow/dags/pg_read_dag.py
[2023-11-23T00:57:15.657+0000] {logging_mixin.py:151} INFO - [2023-11-23T00:57:15.650+0000] {dagbag.py:346} ERROR - Failed to import: /opt/airflow/dags/pg_read_dag.py
Traceback (most recent call last):
  File "/home/airflow/.local/lib/python3.8/site-packages/airflow/models/dagbag.py", line 342, in parse
    loader.exec_module(new_module)
  File "<frozen importlib._bootstrap_external>", line 843, in exec_module
  File "<frozen importlib._bootstrap>", line 219, in _call_with_frames_removed
  File "/opt/airflow/dags/pg_read_dag.py", line 7, in <module>
    postgre_con = BaseHook.get_connection('postgre_sql_conn')
  File "/home/airflow/.local/lib/python3.8/site-packages/airflow/hooks/base.py", line 72, in get_connection
    conn = Connection.get_connection_from_secrets(conn_id)
  File "/home/airflow/.local/lib/python3.8/site-packages/airflow/models/connection.py", line 477, in get_connection_from_secrets
    raise AirflowNotFoundException(f"The conn_id `{conn_id}` isn't defined")
airflow.exceptions.AirflowNotFoundException: The conn_id `postgre_sql_conn` isn't defined
[2023-11-23T00:57:15.658+0000] {processor.py:841} WARNING - No viable dags retrieved from /opt/airflow/dags/pg_read_dag.py
[2023-11-23T00:57:15.671+0000] {processor.py:179} INFO - Processing /opt/airflow/dags/pg_read_dag.py took 0.059 seconds
[2023-11-23T00:57:46.100+0000] {processor.py:157} INFO - Started process (PID=1018) to work on /opt/airflow/dags/pg_read_dag.py
[2023-11-23T00:57:46.101+0000] {processor.py:829} INFO - Processing file /opt/airflow/dags/pg_read_dag.py for tasks to queue
[2023-11-23T00:57:46.103+0000] {logging_mixin.py:151} INFO - [2023-11-23T00:57:46.102+0000] {dagbag.py:536} INFO - Filling up the DagBag from /opt/airflow/dags/pg_read_dag.py
[2023-11-23T00:57:46.142+0000] {logging_mixin.py:151} INFO - [2023-11-23T00:57:46.134+0000] {dagbag.py:346} ERROR - Failed to import: /opt/airflow/dags/pg_read_dag.py
Traceback (most recent call last):
  File "/home/airflow/.local/lib/python3.8/site-packages/airflow/models/dagbag.py", line 342, in parse
    loader.exec_module(new_module)
  File "<frozen importlib._bootstrap_external>", line 843, in exec_module
  File "<frozen importlib._bootstrap>", line 219, in _call_with_frames_removed
  File "/opt/airflow/dags/pg_read_dag.py", line 7, in <module>
    postgre_con = BaseHook.get_connection('postgre_sql_conn')
  File "/home/airflow/.local/lib/python3.8/site-packages/airflow/hooks/base.py", line 72, in get_connection
    conn = Connection.get_connection_from_secrets(conn_id)
  File "/home/airflow/.local/lib/python3.8/site-packages/airflow/models/connection.py", line 477, in get_connection_from_secrets
    raise AirflowNotFoundException(f"The conn_id `{conn_id}` isn't defined")
airflow.exceptions.AirflowNotFoundException: The conn_id `postgre_sql_conn` isn't defined
[2023-11-23T00:57:46.143+0000] {processor.py:841} WARNING - No viable dags retrieved from /opt/airflow/dags/pg_read_dag.py
[2023-11-23T00:57:46.155+0000] {processor.py:179} INFO - Processing /opt/airflow/dags/pg_read_dag.py took 0.058 seconds
[2023-11-23T00:58:16.678+0000] {processor.py:157} INFO - Started process (PID=1035) to work on /opt/airflow/dags/pg_read_dag.py
[2023-11-23T00:58:16.680+0000] {processor.py:829} INFO - Processing file /opt/airflow/dags/pg_read_dag.py for tasks to queue
[2023-11-23T00:58:16.682+0000] {logging_mixin.py:151} INFO - [2023-11-23T00:58:16.681+0000] {dagbag.py:536} INFO - Filling up the DagBag from /opt/airflow/dags/pg_read_dag.py
[2023-11-23T00:58:16.739+0000] {logging_mixin.py:151} INFO - [2023-11-23T00:58:16.730+0000] {dagbag.py:346} ERROR - Failed to import: /opt/airflow/dags/pg_read_dag.py
Traceback (most recent call last):
  File "/home/airflow/.local/lib/python3.8/site-packages/airflow/models/dagbag.py", line 342, in parse
    loader.exec_module(new_module)
  File "<frozen importlib._bootstrap_external>", line 843, in exec_module
  File "<frozen importlib._bootstrap>", line 219, in _call_with_frames_removed
  File "/opt/airflow/dags/pg_read_dag.py", line 7, in <module>
    postgre_con = BaseHook.get_connection('postgre_sql_conn')
  File "/home/airflow/.local/lib/python3.8/site-packages/airflow/hooks/base.py", line 72, in get_connection
    conn = Connection.get_connection_from_secrets(conn_id)
  File "/home/airflow/.local/lib/python3.8/site-packages/airflow/models/connection.py", line 477, in get_connection_from_secrets
    raise AirflowNotFoundException(f"The conn_id `{conn_id}` isn't defined")
airflow.exceptions.AirflowNotFoundException: The conn_id `postgre_sql_conn` isn't defined
[2023-11-23T00:58:16.740+0000] {processor.py:841} WARNING - No viable dags retrieved from /opt/airflow/dags/pg_read_dag.py
[2023-11-23T00:58:16.754+0000] {processor.py:179} INFO - Processing /opt/airflow/dags/pg_read_dag.py took 0.081 seconds
[2023-11-23T00:58:47.189+0000] {processor.py:157} INFO - Started process (PID=1052) to work on /opt/airflow/dags/pg_read_dag.py
[2023-11-23T00:58:47.190+0000] {processor.py:829} INFO - Processing file /opt/airflow/dags/pg_read_dag.py for tasks to queue
[2023-11-23T00:58:47.191+0000] {logging_mixin.py:151} INFO - [2023-11-23T00:58:47.191+0000] {dagbag.py:536} INFO - Filling up the DagBag from /opt/airflow/dags/pg_read_dag.py
[2023-11-23T00:58:47.230+0000] {logging_mixin.py:151} INFO - [2023-11-23T00:58:47.220+0000] {dagbag.py:346} ERROR - Failed to import: /opt/airflow/dags/pg_read_dag.py
Traceback (most recent call last):
  File "/home/airflow/.local/lib/python3.8/site-packages/airflow/models/dagbag.py", line 342, in parse
    loader.exec_module(new_module)
  File "<frozen importlib._bootstrap_external>", line 843, in exec_module
  File "<frozen importlib._bootstrap>", line 219, in _call_with_frames_removed
  File "/opt/airflow/dags/pg_read_dag.py", line 7, in <module>
    postgre_con = BaseHook.get_connection('postgre_sql_conn')
  File "/home/airflow/.local/lib/python3.8/site-packages/airflow/hooks/base.py", line 72, in get_connection
    conn = Connection.get_connection_from_secrets(conn_id)
  File "/home/airflow/.local/lib/python3.8/site-packages/airflow/models/connection.py", line 477, in get_connection_from_secrets
    raise AirflowNotFoundException(f"The conn_id `{conn_id}` isn't defined")
airflow.exceptions.AirflowNotFoundException: The conn_id `postgre_sql_conn` isn't defined
[2023-11-23T00:58:47.230+0000] {processor.py:841} WARNING - No viable dags retrieved from /opt/airflow/dags/pg_read_dag.py
[2023-11-23T00:58:47.242+0000] {processor.py:179} INFO - Processing /opt/airflow/dags/pg_read_dag.py took 0.058 seconds
[2023-11-23T00:59:17.738+0000] {processor.py:157} INFO - Started process (PID=1069) to work on /opt/airflow/dags/pg_read_dag.py
[2023-11-23T00:59:17.739+0000] {processor.py:829} INFO - Processing file /opt/airflow/dags/pg_read_dag.py for tasks to queue
[2023-11-23T00:59:17.740+0000] {logging_mixin.py:151} INFO - [2023-11-23T00:59:17.740+0000] {dagbag.py:536} INFO - Filling up the DagBag from /opt/airflow/dags/pg_read_dag.py
[2023-11-23T00:59:17.785+0000] {logging_mixin.py:151} INFO - [2023-11-23T00:59:17.776+0000] {dagbag.py:346} ERROR - Failed to import: /opt/airflow/dags/pg_read_dag.py
Traceback (most recent call last):
  File "/home/airflow/.local/lib/python3.8/site-packages/airflow/models/dagbag.py", line 342, in parse
    loader.exec_module(new_module)
  File "<frozen importlib._bootstrap_external>", line 843, in exec_module
  File "<frozen importlib._bootstrap>", line 219, in _call_with_frames_removed
  File "/opt/airflow/dags/pg_read_dag.py", line 7, in <module>
    postgre_con = BaseHook.get_connection('postgre_sql_conn')
  File "/home/airflow/.local/lib/python3.8/site-packages/airflow/hooks/base.py", line 72, in get_connection
    conn = Connection.get_connection_from_secrets(conn_id)
  File "/home/airflow/.local/lib/python3.8/site-packages/airflow/models/connection.py", line 477, in get_connection_from_secrets
    raise AirflowNotFoundException(f"The conn_id `{conn_id}` isn't defined")
airflow.exceptions.AirflowNotFoundException: The conn_id `postgre_sql_conn` isn't defined
[2023-11-23T00:59:17.786+0000] {processor.py:841} WARNING - No viable dags retrieved from /opt/airflow/dags/pg_read_dag.py
[2023-11-23T00:59:17.803+0000] {processor.py:179} INFO - Processing /opt/airflow/dags/pg_read_dag.py took 0.069 seconds
[2023-11-23T00:59:48.255+0000] {processor.py:157} INFO - Started process (PID=1086) to work on /opt/airflow/dags/pg_read_dag.py
[2023-11-23T00:59:48.257+0000] {processor.py:829} INFO - Processing file /opt/airflow/dags/pg_read_dag.py for tasks to queue
[2023-11-23T00:59:48.259+0000] {logging_mixin.py:151} INFO - [2023-11-23T00:59:48.258+0000] {dagbag.py:536} INFO - Filling up the DagBag from /opt/airflow/dags/pg_read_dag.py
[2023-11-23T00:59:48.311+0000] {logging_mixin.py:151} INFO - [2023-11-23T00:59:48.302+0000] {dagbag.py:346} ERROR - Failed to import: /opt/airflow/dags/pg_read_dag.py
Traceback (most recent call last):
  File "/home/airflow/.local/lib/python3.8/site-packages/airflow/models/dagbag.py", line 342, in parse
    loader.exec_module(new_module)
  File "<frozen importlib._bootstrap_external>", line 843, in exec_module
  File "<frozen importlib._bootstrap>", line 219, in _call_with_frames_removed
  File "/opt/airflow/dags/pg_read_dag.py", line 7, in <module>
    postgre_con = BaseHook.get_connection('postgre_sql_conn')
  File "/home/airflow/.local/lib/python3.8/site-packages/airflow/hooks/base.py", line 72, in get_connection
    conn = Connection.get_connection_from_secrets(conn_id)
  File "/home/airflow/.local/lib/python3.8/site-packages/airflow/models/connection.py", line 477, in get_connection_from_secrets
    raise AirflowNotFoundException(f"The conn_id `{conn_id}` isn't defined")
airflow.exceptions.AirflowNotFoundException: The conn_id `postgre_sql_conn` isn't defined
[2023-11-23T00:59:48.312+0000] {processor.py:841} WARNING - No viable dags retrieved from /opt/airflow/dags/pg_read_dag.py
[2023-11-23T00:59:48.357+0000] {processor.py:179} INFO - Processing /opt/airflow/dags/pg_read_dag.py took 0.106 seconds
[2023-11-23T01:00:18.740+0000] {processor.py:157} INFO - Started process (PID=1103) to work on /opt/airflow/dags/pg_read_dag.py
[2023-11-23T01:00:18.742+0000] {processor.py:829} INFO - Processing file /opt/airflow/dags/pg_read_dag.py for tasks to queue
[2023-11-23T01:00:18.745+0000] {logging_mixin.py:151} INFO - [2023-11-23T01:00:18.744+0000] {dagbag.py:536} INFO - Filling up the DagBag from /opt/airflow/dags/pg_read_dag.py
[2023-11-23T01:00:18.836+0000] {logging_mixin.py:151} INFO - [2023-11-23T01:00:18.824+0000] {dagbag.py:346} ERROR - Failed to import: /opt/airflow/dags/pg_read_dag.py
Traceback (most recent call last):
  File "/home/airflow/.local/lib/python3.8/site-packages/airflow/models/dagbag.py", line 342, in parse
    loader.exec_module(new_module)
  File "<frozen importlib._bootstrap_external>", line 843, in exec_module
  File "<frozen importlib._bootstrap>", line 219, in _call_with_frames_removed
  File "/opt/airflow/dags/pg_read_dag.py", line 7, in <module>
    postgre_con = BaseHook.get_connection('postgre_sql_conn')
  File "/home/airflow/.local/lib/python3.8/site-packages/airflow/hooks/base.py", line 72, in get_connection
    conn = Connection.get_connection_from_secrets(conn_id)
  File "/home/airflow/.local/lib/python3.8/site-packages/airflow/models/connection.py", line 477, in get_connection_from_secrets
    raise AirflowNotFoundException(f"The conn_id `{conn_id}` isn't defined")
airflow.exceptions.AirflowNotFoundException: The conn_id `postgre_sql_conn` isn't defined
[2023-11-23T01:00:18.838+0000] {processor.py:841} WARNING - No viable dags retrieved from /opt/airflow/dags/pg_read_dag.py
[2023-11-23T01:00:18.881+0000] {processor.py:179} INFO - Processing /opt/airflow/dags/pg_read_dag.py took 0.152 seconds
[2023-11-23T01:00:49.252+0000] {processor.py:157} INFO - Started process (PID=1120) to work on /opt/airflow/dags/pg_read_dag.py
[2023-11-23T01:00:49.254+0000] {processor.py:829} INFO - Processing file /opt/airflow/dags/pg_read_dag.py for tasks to queue
[2023-11-23T01:00:49.256+0000] {logging_mixin.py:151} INFO - [2023-11-23T01:00:49.255+0000] {dagbag.py:536} INFO - Filling up the DagBag from /opt/airflow/dags/pg_read_dag.py
[2023-11-23T01:00:49.309+0000] {logging_mixin.py:151} INFO - [2023-11-23T01:00:49.301+0000] {dagbag.py:346} ERROR - Failed to import: /opt/airflow/dags/pg_read_dag.py
Traceback (most recent call last):
  File "/home/airflow/.local/lib/python3.8/site-packages/airflow/models/dagbag.py", line 342, in parse
    loader.exec_module(new_module)
  File "<frozen importlib._bootstrap_external>", line 843, in exec_module
  File "<frozen importlib._bootstrap>", line 219, in _call_with_frames_removed
  File "/opt/airflow/dags/pg_read_dag.py", line 7, in <module>
    postgre_con = BaseHook.get_connection('postgre_sql_conn')
  File "/home/airflow/.local/lib/python3.8/site-packages/airflow/hooks/base.py", line 72, in get_connection
    conn = Connection.get_connection_from_secrets(conn_id)
  File "/home/airflow/.local/lib/python3.8/site-packages/airflow/models/connection.py", line 477, in get_connection_from_secrets
    raise AirflowNotFoundException(f"The conn_id `{conn_id}` isn't defined")
airflow.exceptions.AirflowNotFoundException: The conn_id `postgre_sql_conn` isn't defined
[2023-11-23T01:00:49.310+0000] {processor.py:841} WARNING - No viable dags retrieved from /opt/airflow/dags/pg_read_dag.py
[2023-11-23T01:00:49.323+0000] {processor.py:179} INFO - Processing /opt/airflow/dags/pg_read_dag.py took 0.077 seconds
[2023-11-23T01:01:19.863+0000] {processor.py:157} INFO - Started process (PID=1137) to work on /opt/airflow/dags/pg_read_dag.py
[2023-11-23T01:01:19.865+0000] {processor.py:829} INFO - Processing file /opt/airflow/dags/pg_read_dag.py for tasks to queue
[2023-11-23T01:01:19.867+0000] {logging_mixin.py:151} INFO - [2023-11-23T01:01:19.866+0000] {dagbag.py:536} INFO - Filling up the DagBag from /opt/airflow/dags/pg_read_dag.py
[2023-11-23T01:01:19.921+0000] {logging_mixin.py:151} INFO - [2023-11-23T01:01:19.914+0000] {dagbag.py:346} ERROR - Failed to import: /opt/airflow/dags/pg_read_dag.py
Traceback (most recent call last):
  File "/home/airflow/.local/lib/python3.8/site-packages/airflow/models/dagbag.py", line 342, in parse
    loader.exec_module(new_module)
  File "<frozen importlib._bootstrap_external>", line 843, in exec_module
  File "<frozen importlib._bootstrap>", line 219, in _call_with_frames_removed
  File "/opt/airflow/dags/pg_read_dag.py", line 7, in <module>
    postgre_con = BaseHook.get_connection('postgre_sql_conn')
  File "/home/airflow/.local/lib/python3.8/site-packages/airflow/hooks/base.py", line 72, in get_connection
    conn = Connection.get_connection_from_secrets(conn_id)
  File "/home/airflow/.local/lib/python3.8/site-packages/airflow/models/connection.py", line 477, in get_connection_from_secrets
    raise AirflowNotFoundException(f"The conn_id `{conn_id}` isn't defined")
airflow.exceptions.AirflowNotFoundException: The conn_id `postgre_sql_conn` isn't defined
[2023-11-23T01:01:19.922+0000] {processor.py:841} WARNING - No viable dags retrieved from /opt/airflow/dags/pg_read_dag.py
[2023-11-23T01:01:19.964+0000] {processor.py:179} INFO - Processing /opt/airflow/dags/pg_read_dag.py took 0.105 seconds
[2023-11-23T01:01:50.338+0000] {processor.py:157} INFO - Started process (PID=1154) to work on /opt/airflow/dags/pg_read_dag.py
[2023-11-23T01:01:50.340+0000] {processor.py:829} INFO - Processing file /opt/airflow/dags/pg_read_dag.py for tasks to queue
[2023-11-23T01:01:50.341+0000] {logging_mixin.py:151} INFO - [2023-11-23T01:01:50.341+0000] {dagbag.py:536} INFO - Filling up the DagBag from /opt/airflow/dags/pg_read_dag.py
[2023-11-23T01:01:50.391+0000] {logging_mixin.py:151} INFO - [2023-11-23T01:01:50.384+0000] {dagbag.py:346} ERROR - Failed to import: /opt/airflow/dags/pg_read_dag.py
Traceback (most recent call last):
  File "/home/airflow/.local/lib/python3.8/site-packages/airflow/models/dagbag.py", line 342, in parse
    loader.exec_module(new_module)
  File "<frozen importlib._bootstrap_external>", line 843, in exec_module
  File "<frozen importlib._bootstrap>", line 219, in _call_with_frames_removed
  File "/opt/airflow/dags/pg_read_dag.py", line 7, in <module>
    postgre_con = BaseHook.get_connection('postgre_sql_conn')
  File "/home/airflow/.local/lib/python3.8/site-packages/airflow/hooks/base.py", line 72, in get_connection
    conn = Connection.get_connection_from_secrets(conn_id)
  File "/home/airflow/.local/lib/python3.8/site-packages/airflow/models/connection.py", line 477, in get_connection_from_secrets
    raise AirflowNotFoundException(f"The conn_id `{conn_id}` isn't defined")
airflow.exceptions.AirflowNotFoundException: The conn_id `postgre_sql_conn` isn't defined
[2023-11-23T01:01:50.391+0000] {processor.py:841} WARNING - No viable dags retrieved from /opt/airflow/dags/pg_read_dag.py
[2023-11-23T01:01:50.407+0000] {processor.py:179} INFO - Processing /opt/airflow/dags/pg_read_dag.py took 0.073 seconds
[2023-11-23T01:02:20.883+0000] {processor.py:157} INFO - Started process (PID=1171) to work on /opt/airflow/dags/pg_read_dag.py
[2023-11-23T01:02:20.884+0000] {processor.py:829} INFO - Processing file /opt/airflow/dags/pg_read_dag.py for tasks to queue
[2023-11-23T01:02:20.885+0000] {logging_mixin.py:151} INFO - [2023-11-23T01:02:20.885+0000] {dagbag.py:536} INFO - Filling up the DagBag from /opt/airflow/dags/pg_read_dag.py
[2023-11-23T01:02:20.920+0000] {logging_mixin.py:151} INFO - [2023-11-23T01:02:20.915+0000] {dagbag.py:346} ERROR - Failed to import: /opt/airflow/dags/pg_read_dag.py
Traceback (most recent call last):
  File "/home/airflow/.local/lib/python3.8/site-packages/airflow/models/dagbag.py", line 342, in parse
    loader.exec_module(new_module)
  File "<frozen importlib._bootstrap_external>", line 843, in exec_module
  File "<frozen importlib._bootstrap>", line 219, in _call_with_frames_removed
  File "/opt/airflow/dags/pg_read_dag.py", line 7, in <module>
    postgre_con = BaseHook.get_connection('postgre_sql_conn')
  File "/home/airflow/.local/lib/python3.8/site-packages/airflow/hooks/base.py", line 72, in get_connection
    conn = Connection.get_connection_from_secrets(conn_id)
  File "/home/airflow/.local/lib/python3.8/site-packages/airflow/models/connection.py", line 477, in get_connection_from_secrets
    raise AirflowNotFoundException(f"The conn_id `{conn_id}` isn't defined")
airflow.exceptions.AirflowNotFoundException: The conn_id `postgre_sql_conn` isn't defined
[2023-11-23T01:02:20.921+0000] {processor.py:841} WARNING - No viable dags retrieved from /opt/airflow/dags/pg_read_dag.py
[2023-11-23T01:02:20.933+0000] {processor.py:179} INFO - Processing /opt/airflow/dags/pg_read_dag.py took 0.057 seconds
[2023-11-23T01:02:51.395+0000] {processor.py:157} INFO - Started process (PID=1188) to work on /opt/airflow/dags/pg_read_dag.py
[2023-11-23T01:02:51.396+0000] {processor.py:829} INFO - Processing file /opt/airflow/dags/pg_read_dag.py for tasks to queue
[2023-11-23T01:02:51.398+0000] {logging_mixin.py:151} INFO - [2023-11-23T01:02:51.397+0000] {dagbag.py:536} INFO - Filling up the DagBag from /opt/airflow/dags/pg_read_dag.py
[2023-11-23T01:02:51.437+0000] {logging_mixin.py:151} INFO - [2023-11-23T01:02:51.432+0000] {dagbag.py:346} ERROR - Failed to import: /opt/airflow/dags/pg_read_dag.py
Traceback (most recent call last):
  File "/home/airflow/.local/lib/python3.8/site-packages/airflow/models/dagbag.py", line 342, in parse
    loader.exec_module(new_module)
  File "<frozen importlib._bootstrap_external>", line 843, in exec_module
  File "<frozen importlib._bootstrap>", line 219, in _call_with_frames_removed
  File "/opt/airflow/dags/pg_read_dag.py", line 7, in <module>
    postgre_con = BaseHook.get_connection('postgre_sql_conn')
  File "/home/airflow/.local/lib/python3.8/site-packages/airflow/hooks/base.py", line 72, in get_connection
    conn = Connection.get_connection_from_secrets(conn_id)
  File "/home/airflow/.local/lib/python3.8/site-packages/airflow/models/connection.py", line 477, in get_connection_from_secrets
    raise AirflowNotFoundException(f"The conn_id `{conn_id}` isn't defined")
airflow.exceptions.AirflowNotFoundException: The conn_id `postgre_sql_conn` isn't defined
[2023-11-23T01:02:51.438+0000] {processor.py:841} WARNING - No viable dags retrieved from /opt/airflow/dags/pg_read_dag.py
[2023-11-23T01:02:51.451+0000] {processor.py:179} INFO - Processing /opt/airflow/dags/pg_read_dag.py took 0.060 seconds
[2023-11-23T01:03:21.882+0000] {processor.py:157} INFO - Started process (PID=1205) to work on /opt/airflow/dags/pg_read_dag.py
[2023-11-23T01:03:21.883+0000] {processor.py:829} INFO - Processing file /opt/airflow/dags/pg_read_dag.py for tasks to queue
[2023-11-23T01:03:21.885+0000] {logging_mixin.py:151} INFO - [2023-11-23T01:03:21.884+0000] {dagbag.py:536} INFO - Filling up the DagBag from /opt/airflow/dags/pg_read_dag.py
[2023-11-23T01:03:21.931+0000] {logging_mixin.py:151} INFO - [2023-11-23T01:03:21.922+0000] {dagbag.py:346} ERROR - Failed to import: /opt/airflow/dags/pg_read_dag.py
Traceback (most recent call last):
  File "/home/airflow/.local/lib/python3.8/site-packages/airflow/models/dagbag.py", line 342, in parse
    loader.exec_module(new_module)
  File "<frozen importlib._bootstrap_external>", line 843, in exec_module
  File "<frozen importlib._bootstrap>", line 219, in _call_with_frames_removed
  File "/opt/airflow/dags/pg_read_dag.py", line 7, in <module>
    postgre_con = BaseHook.get_connection('postgre_sql_conn')
  File "/home/airflow/.local/lib/python3.8/site-packages/airflow/hooks/base.py", line 72, in get_connection
    conn = Connection.get_connection_from_secrets(conn_id)
  File "/home/airflow/.local/lib/python3.8/site-packages/airflow/models/connection.py", line 477, in get_connection_from_secrets
    raise AirflowNotFoundException(f"The conn_id `{conn_id}` isn't defined")
airflow.exceptions.AirflowNotFoundException: The conn_id `postgre_sql_conn` isn't defined
[2023-11-23T01:03:21.932+0000] {processor.py:841} WARNING - No viable dags retrieved from /opt/airflow/dags/pg_read_dag.py
[2023-11-23T01:03:21.973+0000] {processor.py:179} INFO - Processing /opt/airflow/dags/pg_read_dag.py took 0.095 seconds
[2023-11-23T01:03:52.404+0000] {processor.py:157} INFO - Started process (PID=1222) to work on /opt/airflow/dags/pg_read_dag.py
[2023-11-23T01:03:52.406+0000] {processor.py:829} INFO - Processing file /opt/airflow/dags/pg_read_dag.py for tasks to queue
[2023-11-23T01:03:52.409+0000] {logging_mixin.py:151} INFO - [2023-11-23T01:03:52.408+0000] {dagbag.py:536} INFO - Filling up the DagBag from /opt/airflow/dags/pg_read_dag.py
[2023-11-23T01:03:52.461+0000] {logging_mixin.py:151} INFO - [2023-11-23T01:03:52.454+0000] {dagbag.py:346} ERROR - Failed to import: /opt/airflow/dags/pg_read_dag.py
Traceback (most recent call last):
  File "/home/airflow/.local/lib/python3.8/site-packages/airflow/models/dagbag.py", line 342, in parse
    loader.exec_module(new_module)
  File "<frozen importlib._bootstrap_external>", line 843, in exec_module
  File "<frozen importlib._bootstrap>", line 219, in _call_with_frames_removed
  File "/opt/airflow/dags/pg_read_dag.py", line 7, in <module>
    postgre_con = BaseHook.get_connection('postgre_sql_conn')
  File "/home/airflow/.local/lib/python3.8/site-packages/airflow/hooks/base.py", line 72, in get_connection
    conn = Connection.get_connection_from_secrets(conn_id)
  File "/home/airflow/.local/lib/python3.8/site-packages/airflow/models/connection.py", line 477, in get_connection_from_secrets
    raise AirflowNotFoundException(f"The conn_id `{conn_id}` isn't defined")
airflow.exceptions.AirflowNotFoundException: The conn_id `postgre_sql_conn` isn't defined
[2023-11-23T01:03:52.462+0000] {processor.py:841} WARNING - No viable dags retrieved from /opt/airflow/dags/pg_read_dag.py
[2023-11-23T01:03:52.475+0000] {processor.py:179} INFO - Processing /opt/airflow/dags/pg_read_dag.py took 0.077 seconds
[2023-11-23T01:04:22.943+0000] {processor.py:157} INFO - Started process (PID=1239) to work on /opt/airflow/dags/pg_read_dag.py
[2023-11-23T01:04:22.945+0000] {processor.py:829} INFO - Processing file /opt/airflow/dags/pg_read_dag.py for tasks to queue
[2023-11-23T01:04:22.946+0000] {logging_mixin.py:151} INFO - [2023-11-23T01:04:22.946+0000] {dagbag.py:536} INFO - Filling up the DagBag from /opt/airflow/dags/pg_read_dag.py
[2023-11-23T01:04:22.990+0000] {logging_mixin.py:151} INFO - [2023-11-23T01:04:22.984+0000] {dagbag.py:346} ERROR - Failed to import: /opt/airflow/dags/pg_read_dag.py
Traceback (most recent call last):
  File "/home/airflow/.local/lib/python3.8/site-packages/airflow/models/dagbag.py", line 342, in parse
    loader.exec_module(new_module)
  File "<frozen importlib._bootstrap_external>", line 843, in exec_module
  File "<frozen importlib._bootstrap>", line 219, in _call_with_frames_removed
  File "/opt/airflow/dags/pg_read_dag.py", line 7, in <module>
    postgre_con = BaseHook.get_connection('postgre_sql_conn')
  File "/home/airflow/.local/lib/python3.8/site-packages/airflow/hooks/base.py", line 72, in get_connection
    conn = Connection.get_connection_from_secrets(conn_id)
  File "/home/airflow/.local/lib/python3.8/site-packages/airflow/models/connection.py", line 477, in get_connection_from_secrets
    raise AirflowNotFoundException(f"The conn_id `{conn_id}` isn't defined")
airflow.exceptions.AirflowNotFoundException: The conn_id `postgre_sql_conn` isn't defined
[2023-11-23T01:04:22.992+0000] {processor.py:841} WARNING - No viable dags retrieved from /opt/airflow/dags/pg_read_dag.py
[2023-11-23T01:04:23.040+0000] {processor.py:179} INFO - Processing /opt/airflow/dags/pg_read_dag.py took 0.101 seconds
[2023-11-23T01:04:53.461+0000] {processor.py:157} INFO - Started process (PID=1256) to work on /opt/airflow/dags/pg_read_dag.py
[2023-11-23T01:04:53.463+0000] {processor.py:829} INFO - Processing file /opt/airflow/dags/pg_read_dag.py for tasks to queue
[2023-11-23T01:04:53.465+0000] {logging_mixin.py:151} INFO - [2023-11-23T01:04:53.465+0000] {dagbag.py:536} INFO - Filling up the DagBag from /opt/airflow/dags/pg_read_dag.py
[2023-11-23T01:04:53.525+0000] {logging_mixin.py:151} INFO - [2023-11-23T01:04:53.517+0000] {dagbag.py:346} ERROR - Failed to import: /opt/airflow/dags/pg_read_dag.py
Traceback (most recent call last):
  File "/home/airflow/.local/lib/python3.8/site-packages/airflow/models/dagbag.py", line 342, in parse
    loader.exec_module(new_module)
  File "<frozen importlib._bootstrap_external>", line 843, in exec_module
  File "<frozen importlib._bootstrap>", line 219, in _call_with_frames_removed
  File "/opt/airflow/dags/pg_read_dag.py", line 7, in <module>
    postgre_con = BaseHook.get_connection('postgre_sql_conn')
  File "/home/airflow/.local/lib/python3.8/site-packages/airflow/hooks/base.py", line 72, in get_connection
    conn = Connection.get_connection_from_secrets(conn_id)
  File "/home/airflow/.local/lib/python3.8/site-packages/airflow/models/connection.py", line 477, in get_connection_from_secrets
    raise AirflowNotFoundException(f"The conn_id `{conn_id}` isn't defined")
airflow.exceptions.AirflowNotFoundException: The conn_id `postgre_sql_conn` isn't defined
[2023-11-23T01:04:53.526+0000] {processor.py:841} WARNING - No viable dags retrieved from /opt/airflow/dags/pg_read_dag.py
[2023-11-23T01:04:53.562+0000] {processor.py:179} INFO - Processing /opt/airflow/dags/pg_read_dag.py took 0.109 seconds
[2023-11-23T01:05:23.879+0000] {processor.py:157} INFO - Started process (PID=1273) to work on /opt/airflow/dags/pg_read_dag.py
[2023-11-23T01:05:23.881+0000] {processor.py:829} INFO - Processing file /opt/airflow/dags/pg_read_dag.py for tasks to queue
[2023-11-23T01:05:23.882+0000] {logging_mixin.py:151} INFO - [2023-11-23T01:05:23.882+0000] {dagbag.py:536} INFO - Filling up the DagBag from /opt/airflow/dags/pg_read_dag.py
[2023-11-23T01:05:23.926+0000] {logging_mixin.py:151} INFO - [2023-11-23T01:05:23.920+0000] {dagbag.py:346} ERROR - Failed to import: /opt/airflow/dags/pg_read_dag.py
Traceback (most recent call last):
  File "/home/airflow/.local/lib/python3.8/site-packages/airflow/models/dagbag.py", line 342, in parse
    loader.exec_module(new_module)
  File "<frozen importlib._bootstrap_external>", line 843, in exec_module
  File "<frozen importlib._bootstrap>", line 219, in _call_with_frames_removed
  File "/opt/airflow/dags/pg_read_dag.py", line 7, in <module>
    postgre_con = BaseHook.get_connection('postgre_sql_conn')
  File "/home/airflow/.local/lib/python3.8/site-packages/airflow/hooks/base.py", line 72, in get_connection
    conn = Connection.get_connection_from_secrets(conn_id)
  File "/home/airflow/.local/lib/python3.8/site-packages/airflow/models/connection.py", line 477, in get_connection_from_secrets
    raise AirflowNotFoundException(f"The conn_id `{conn_id}` isn't defined")
airflow.exceptions.AirflowNotFoundException: The conn_id `postgre_sql_conn` isn't defined
[2023-11-23T01:05:23.927+0000] {processor.py:841} WARNING - No viable dags retrieved from /opt/airflow/dags/pg_read_dag.py
[2023-11-23T01:05:23.939+0000] {processor.py:179} INFO - Processing /opt/airflow/dags/pg_read_dag.py took 0.064 seconds
[2023-11-23T01:05:54.462+0000] {processor.py:157} INFO - Started process (PID=1290) to work on /opt/airflow/dags/pg_read_dag.py
[2023-11-23T01:05:54.464+0000] {processor.py:829} INFO - Processing file /opt/airflow/dags/pg_read_dag.py for tasks to queue
[2023-11-23T01:05:54.466+0000] {logging_mixin.py:151} INFO - [2023-11-23T01:05:54.466+0000] {dagbag.py:536} INFO - Filling up the DagBag from /opt/airflow/dags/pg_read_dag.py
[2023-11-23T01:05:54.530+0000] {logging_mixin.py:151} INFO - [2023-11-23T01:05:54.520+0000] {dagbag.py:346} ERROR - Failed to import: /opt/airflow/dags/pg_read_dag.py
Traceback (most recent call last):
  File "/home/airflow/.local/lib/python3.8/site-packages/airflow/models/dagbag.py", line 342, in parse
    loader.exec_module(new_module)
  File "<frozen importlib._bootstrap_external>", line 843, in exec_module
  File "<frozen importlib._bootstrap>", line 219, in _call_with_frames_removed
  File "/opt/airflow/dags/pg_read_dag.py", line 7, in <module>
    postgre_con = BaseHook.get_connection('postgre_sql_conn')
  File "/home/airflow/.local/lib/python3.8/site-packages/airflow/hooks/base.py", line 72, in get_connection
    conn = Connection.get_connection_from_secrets(conn_id)
  File "/home/airflow/.local/lib/python3.8/site-packages/airflow/models/connection.py", line 477, in get_connection_from_secrets
    raise AirflowNotFoundException(f"The conn_id `{conn_id}` isn't defined")
airflow.exceptions.AirflowNotFoundException: The conn_id `postgre_sql_conn` isn't defined
[2023-11-23T01:05:54.532+0000] {processor.py:841} WARNING - No viable dags retrieved from /opt/airflow/dags/pg_read_dag.py
[2023-11-23T01:05:54.589+0000] {processor.py:179} INFO - Processing /opt/airflow/dags/pg_read_dag.py took 0.133 seconds
[2023-11-23T01:06:25.055+0000] {processor.py:157} INFO - Started process (PID=1307) to work on /opt/airflow/dags/pg_read_dag.py
[2023-11-23T01:06:25.056+0000] {processor.py:829} INFO - Processing file /opt/airflow/dags/pg_read_dag.py for tasks to queue
[2023-11-23T01:06:25.057+0000] {logging_mixin.py:151} INFO - [2023-11-23T01:06:25.057+0000] {dagbag.py:536} INFO - Filling up the DagBag from /opt/airflow/dags/pg_read_dag.py
[2023-11-23T01:06:25.105+0000] {logging_mixin.py:151} INFO - [2023-11-23T01:06:25.096+0000] {dagbag.py:346} ERROR - Failed to import: /opt/airflow/dags/pg_read_dag.py
Traceback (most recent call last):
  File "/home/airflow/.local/lib/python3.8/site-packages/airflow/models/dagbag.py", line 342, in parse
    loader.exec_module(new_module)
  File "<frozen importlib._bootstrap_external>", line 843, in exec_module
  File "<frozen importlib._bootstrap>", line 219, in _call_with_frames_removed
  File "/opt/airflow/dags/pg_read_dag.py", line 7, in <module>
    postgre_con = BaseHook.get_connection('postgre_sql_conn')
  File "/home/airflow/.local/lib/python3.8/site-packages/airflow/hooks/base.py", line 72, in get_connection
    conn = Connection.get_connection_from_secrets(conn_id)
  File "/home/airflow/.local/lib/python3.8/site-packages/airflow/models/connection.py", line 477, in get_connection_from_secrets
    raise AirflowNotFoundException(f"The conn_id `{conn_id}` isn't defined")
airflow.exceptions.AirflowNotFoundException: The conn_id `postgre_sql_conn` isn't defined
[2023-11-23T01:06:25.106+0000] {processor.py:841} WARNING - No viable dags retrieved from /opt/airflow/dags/pg_read_dag.py
[2023-11-23T01:06:25.146+0000] {processor.py:179} INFO - Processing /opt/airflow/dags/pg_read_dag.py took 0.094 seconds
[2023-11-23T01:06:55.495+0000] {processor.py:157} INFO - Started process (PID=1324) to work on /opt/airflow/dags/pg_read_dag.py
[2023-11-23T01:06:55.498+0000] {processor.py:829} INFO - Processing file /opt/airflow/dags/pg_read_dag.py for tasks to queue
[2023-11-23T01:06:55.500+0000] {logging_mixin.py:151} INFO - [2023-11-23T01:06:55.500+0000] {dagbag.py:536} INFO - Filling up the DagBag from /opt/airflow/dags/pg_read_dag.py
[2023-11-23T01:06:55.542+0000] {logging_mixin.py:151} INFO - [2023-11-23T01:06:55.537+0000] {dagbag.py:346} ERROR - Failed to import: /opt/airflow/dags/pg_read_dag.py
Traceback (most recent call last):
  File "/home/airflow/.local/lib/python3.8/site-packages/airflow/models/dagbag.py", line 342, in parse
    loader.exec_module(new_module)
  File "<frozen importlib._bootstrap_external>", line 843, in exec_module
  File "<frozen importlib._bootstrap>", line 219, in _call_with_frames_removed
  File "/opt/airflow/dags/pg_read_dag.py", line 7, in <module>
    postgre_con = BaseHook.get_connection('postgre_sql_conn')
  File "/home/airflow/.local/lib/python3.8/site-packages/airflow/hooks/base.py", line 72, in get_connection
    conn = Connection.get_connection_from_secrets(conn_id)
  File "/home/airflow/.local/lib/python3.8/site-packages/airflow/models/connection.py", line 477, in get_connection_from_secrets
    raise AirflowNotFoundException(f"The conn_id `{conn_id}` isn't defined")
airflow.exceptions.AirflowNotFoundException: The conn_id `postgre_sql_conn` isn't defined
[2023-11-23T01:06:55.543+0000] {processor.py:841} WARNING - No viable dags retrieved from /opt/airflow/dags/pg_read_dag.py
[2023-11-23T01:06:55.594+0000] {processor.py:179} INFO - Processing /opt/airflow/dags/pg_read_dag.py took 0.106 seconds
[2023-11-23T01:07:26.044+0000] {processor.py:157} INFO - Started process (PID=1341) to work on /opt/airflow/dags/pg_read_dag.py
[2023-11-23T01:07:26.046+0000] {processor.py:829} INFO - Processing file /opt/airflow/dags/pg_read_dag.py for tasks to queue
[2023-11-23T01:07:26.047+0000] {logging_mixin.py:151} INFO - [2023-11-23T01:07:26.047+0000] {dagbag.py:536} INFO - Filling up the DagBag from /opt/airflow/dags/pg_read_dag.py
[2023-11-23T01:07:26.093+0000] {logging_mixin.py:151} INFO - [2023-11-23T01:07:26.087+0000] {dagbag.py:346} ERROR - Failed to import: /opt/airflow/dags/pg_read_dag.py
Traceback (most recent call last):
  File "/home/airflow/.local/lib/python3.8/site-packages/airflow/models/dagbag.py", line 342, in parse
    loader.exec_module(new_module)
  File "<frozen importlib._bootstrap_external>", line 843, in exec_module
  File "<frozen importlib._bootstrap>", line 219, in _call_with_frames_removed
  File "/opt/airflow/dags/pg_read_dag.py", line 7, in <module>
    postgre_con = BaseHook.get_connection('postgre_sql_conn')
  File "/home/airflow/.local/lib/python3.8/site-packages/airflow/hooks/base.py", line 72, in get_connection
    conn = Connection.get_connection_from_secrets(conn_id)
  File "/home/airflow/.local/lib/python3.8/site-packages/airflow/models/connection.py", line 477, in get_connection_from_secrets
    raise AirflowNotFoundException(f"The conn_id `{conn_id}` isn't defined")
airflow.exceptions.AirflowNotFoundException: The conn_id `postgre_sql_conn` isn't defined
[2023-11-23T01:07:26.094+0000] {processor.py:841} WARNING - No viable dags retrieved from /opt/airflow/dags/pg_read_dag.py
[2023-11-23T01:07:26.105+0000] {processor.py:179} INFO - Processing /opt/airflow/dags/pg_read_dag.py took 0.067 seconds
[2023-11-23T01:07:56.506+0000] {processor.py:157} INFO - Started process (PID=1358) to work on /opt/airflow/dags/pg_read_dag.py
[2023-11-23T01:07:56.507+0000] {processor.py:829} INFO - Processing file /opt/airflow/dags/pg_read_dag.py for tasks to queue
[2023-11-23T01:07:56.508+0000] {logging_mixin.py:151} INFO - [2023-11-23T01:07:56.508+0000] {dagbag.py:536} INFO - Filling up the DagBag from /opt/airflow/dags/pg_read_dag.py
[2023-11-23T01:07:56.553+0000] {logging_mixin.py:151} INFO - [2023-11-23T01:07:56.545+0000] {dagbag.py:346} ERROR - Failed to import: /opt/airflow/dags/pg_read_dag.py
Traceback (most recent call last):
  File "/home/airflow/.local/lib/python3.8/site-packages/airflow/models/dagbag.py", line 342, in parse
    loader.exec_module(new_module)
  File "<frozen importlib._bootstrap_external>", line 843, in exec_module
  File "<frozen importlib._bootstrap>", line 219, in _call_with_frames_removed
  File "/opt/airflow/dags/pg_read_dag.py", line 7, in <module>
    postgre_con = BaseHook.get_connection('postgre_sql_conn')
  File "/home/airflow/.local/lib/python3.8/site-packages/airflow/hooks/base.py", line 72, in get_connection
    conn = Connection.get_connection_from_secrets(conn_id)
  File "/home/airflow/.local/lib/python3.8/site-packages/airflow/models/connection.py", line 477, in get_connection_from_secrets
    raise AirflowNotFoundException(f"The conn_id `{conn_id}` isn't defined")
airflow.exceptions.AirflowNotFoundException: The conn_id `postgre_sql_conn` isn't defined
[2023-11-23T01:07:56.553+0000] {processor.py:841} WARNING - No viable dags retrieved from /opt/airflow/dags/pg_read_dag.py
[2023-11-23T01:07:56.595+0000] {processor.py:179} INFO - Processing /opt/airflow/dags/pg_read_dag.py took 0.092 seconds
[2023-11-23T01:08:26.994+0000] {processor.py:157} INFO - Started process (PID=1375) to work on /opt/airflow/dags/pg_read_dag.py
[2023-11-23T01:08:26.995+0000] {processor.py:829} INFO - Processing file /opt/airflow/dags/pg_read_dag.py for tasks to queue
[2023-11-23T01:08:26.996+0000] {logging_mixin.py:151} INFO - [2023-11-23T01:08:26.996+0000] {dagbag.py:536} INFO - Filling up the DagBag from /opt/airflow/dags/pg_read_dag.py
[2023-11-23T01:08:27.039+0000] {logging_mixin.py:151} INFO - [2023-11-23T01:08:27.031+0000] {dagbag.py:346} ERROR - Failed to import: /opt/airflow/dags/pg_read_dag.py
Traceback (most recent call last):
  File "/home/airflow/.local/lib/python3.8/site-packages/airflow/models/dagbag.py", line 342, in parse
    loader.exec_module(new_module)
  File "<frozen importlib._bootstrap_external>", line 843, in exec_module
  File "<frozen importlib._bootstrap>", line 219, in _call_with_frames_removed
  File "/opt/airflow/dags/pg_read_dag.py", line 7, in <module>
    postgre_con = BaseHook.get_connection('postgre_sql_conn')
  File "/home/airflow/.local/lib/python3.8/site-packages/airflow/hooks/base.py", line 72, in get_connection
    conn = Connection.get_connection_from_secrets(conn_id)
  File "/home/airflow/.local/lib/python3.8/site-packages/airflow/models/connection.py", line 477, in get_connection_from_secrets
    raise AirflowNotFoundException(f"The conn_id `{conn_id}` isn't defined")
airflow.exceptions.AirflowNotFoundException: The conn_id `postgre_sql_conn` isn't defined
[2023-11-23T01:08:27.041+0000] {processor.py:841} WARNING - No viable dags retrieved from /opt/airflow/dags/pg_read_dag.py
[2023-11-23T01:08:27.055+0000] {processor.py:179} INFO - Processing /opt/airflow/dags/pg_read_dag.py took 0.064 seconds
[2023-11-23T01:08:32.180+0000] {processor.py:157} INFO - Started process (PID=1382) to work on /opt/airflow/dags/pg_read_dag.py
[2023-11-23T01:08:32.181+0000] {processor.py:829} INFO - Processing file /opt/airflow/dags/pg_read_dag.py for tasks to queue
[2023-11-23T01:08:32.182+0000] {logging_mixin.py:151} INFO - [2023-11-23T01:08:32.182+0000] {dagbag.py:536} INFO - Filling up the DagBag from /opt/airflow/dags/pg_read_dag.py
[2023-11-23T01:08:32.248+0000] {logging_mixin.py:151} INFO - [2023-11-23T01:08:32.240+0000] {dagbag.py:346} ERROR - Failed to import: /opt/airflow/dags/pg_read_dag.py
Traceback (most recent call last):
  File "/home/airflow/.local/lib/python3.8/site-packages/airflow/models/dagbag.py", line 342, in parse
    loader.exec_module(new_module)
  File "<frozen importlib._bootstrap_external>", line 843, in exec_module
  File "<frozen importlib._bootstrap>", line 219, in _call_with_frames_removed
  File "/opt/airflow/dags/pg_read_dag.py", line 7, in <module>
    postgre_con = BaseHook.get_connection('postgre_sql_conn')
  File "/home/airflow/.local/lib/python3.8/site-packages/airflow/hooks/base.py", line 72, in get_connection
    conn = Connection.get_connection_from_secrets(conn_id)
  File "/home/airflow/.local/lib/python3.8/site-packages/airflow/models/connection.py", line 477, in get_connection_from_secrets
    raise AirflowNotFoundException(f"The conn_id `{conn_id}` isn't defined")
airflow.exceptions.AirflowNotFoundException: The conn_id `postgre_sql_conn` isn't defined
[2023-11-23T01:08:32.250+0000] {processor.py:841} WARNING - No viable dags retrieved from /opt/airflow/dags/pg_read_dag.py
[2023-11-23T01:08:32.268+0000] {processor.py:179} INFO - Processing /opt/airflow/dags/pg_read_dag.py took 0.091 seconds
[2023-11-23T01:09:02.726+0000] {processor.py:157} INFO - Started process (PID=1399) to work on /opt/airflow/dags/pg_read_dag.py
[2023-11-23T01:09:02.728+0000] {processor.py:829} INFO - Processing file /opt/airflow/dags/pg_read_dag.py for tasks to queue
[2023-11-23T01:09:02.730+0000] {logging_mixin.py:151} INFO - [2023-11-23T01:09:02.730+0000] {dagbag.py:536} INFO - Filling up the DagBag from /opt/airflow/dags/pg_read_dag.py
[2023-11-23T01:09:02.803+0000] {logging_mixin.py:151} INFO - [2023-11-23T01:09:02.794+0000] {dagbag.py:346} ERROR - Failed to import: /opt/airflow/dags/pg_read_dag.py
Traceback (most recent call last):
  File "/home/airflow/.local/lib/python3.8/site-packages/airflow/models/dagbag.py", line 342, in parse
    loader.exec_module(new_module)
  File "<frozen importlib._bootstrap_external>", line 843, in exec_module
  File "<frozen importlib._bootstrap>", line 219, in _call_with_frames_removed
  File "/opt/airflow/dags/pg_read_dag.py", line 7, in <module>
    postgre_con = BaseHook.get_connection('postgre_sql_conn')
  File "/home/airflow/.local/lib/python3.8/site-packages/airflow/hooks/base.py", line 72, in get_connection
    conn = Connection.get_connection_from_secrets(conn_id)
  File "/home/airflow/.local/lib/python3.8/site-packages/airflow/models/connection.py", line 477, in get_connection_from_secrets
    raise AirflowNotFoundException(f"The conn_id `{conn_id}` isn't defined")
airflow.exceptions.AirflowNotFoundException: The conn_id `postgre_sql_conn` isn't defined
[2023-11-23T01:09:02.804+0000] {processor.py:841} WARNING - No viable dags retrieved from /opt/airflow/dags/pg_read_dag.py
[2023-11-23T01:09:02.815+0000] {processor.py:179} INFO - Processing /opt/airflow/dags/pg_read_dag.py took 0.096 seconds
[2023-11-23T01:09:33.261+0000] {processor.py:157} INFO - Started process (PID=1416) to work on /opt/airflow/dags/pg_read_dag.py
[2023-11-23T01:09:33.263+0000] {processor.py:829} INFO - Processing file /opt/airflow/dags/pg_read_dag.py for tasks to queue
[2023-11-23T01:09:33.264+0000] {logging_mixin.py:151} INFO - [2023-11-23T01:09:33.264+0000] {dagbag.py:536} INFO - Filling up the DagBag from /opt/airflow/dags/pg_read_dag.py
[2023-11-23T01:09:33.333+0000] {logging_mixin.py:151} INFO - [2023-11-23T01:09:33.325+0000] {dagbag.py:346} ERROR - Failed to import: /opt/airflow/dags/pg_read_dag.py
Traceback (most recent call last):
  File "/home/airflow/.local/lib/python3.8/site-packages/airflow/models/dagbag.py", line 342, in parse
    loader.exec_module(new_module)
  File "<frozen importlib._bootstrap_external>", line 843, in exec_module
  File "<frozen importlib._bootstrap>", line 219, in _call_with_frames_removed
  File "/opt/airflow/dags/pg_read_dag.py", line 7, in <module>
    postgre_con = BaseHook.get_connection('postgre_sql_conn')
  File "/home/airflow/.local/lib/python3.8/site-packages/airflow/hooks/base.py", line 72, in get_connection
    conn = Connection.get_connection_from_secrets(conn_id)
  File "/home/airflow/.local/lib/python3.8/site-packages/airflow/models/connection.py", line 477, in get_connection_from_secrets
    raise AirflowNotFoundException(f"The conn_id `{conn_id}` isn't defined")
airflow.exceptions.AirflowNotFoundException: The conn_id `postgre_sql_conn` isn't defined
[2023-11-23T01:09:33.334+0000] {processor.py:841} WARNING - No viable dags retrieved from /opt/airflow/dags/pg_read_dag.py
[2023-11-23T01:09:33.346+0000] {processor.py:179} INFO - Processing /opt/airflow/dags/pg_read_dag.py took 0.089 seconds
[2023-11-23T01:10:03.755+0000] {processor.py:157} INFO - Started process (PID=1434) to work on /opt/airflow/dags/pg_read_dag.py
[2023-11-23T01:10:03.757+0000] {processor.py:829} INFO - Processing file /opt/airflow/dags/pg_read_dag.py for tasks to queue
[2023-11-23T01:10:03.759+0000] {logging_mixin.py:151} INFO - [2023-11-23T01:10:03.759+0000] {dagbag.py:536} INFO - Filling up the DagBag from /opt/airflow/dags/pg_read_dag.py
[2023-11-23T01:10:03.823+0000] {logging_mixin.py:151} INFO - [2023-11-23T01:10:03.814+0000] {dagbag.py:346} ERROR - Failed to import: /opt/airflow/dags/pg_read_dag.py
Traceback (most recent call last):
  File "/home/airflow/.local/lib/python3.8/site-packages/airflow/models/dagbag.py", line 342, in parse
    loader.exec_module(new_module)
  File "<frozen importlib._bootstrap_external>", line 843, in exec_module
  File "<frozen importlib._bootstrap>", line 219, in _call_with_frames_removed
  File "/opt/airflow/dags/pg_read_dag.py", line 7, in <module>
    postgre_con = BaseHook.get_connection('postgre_sql_conn')
  File "/home/airflow/.local/lib/python3.8/site-packages/airflow/hooks/base.py", line 72, in get_connection
    conn = Connection.get_connection_from_secrets(conn_id)
  File "/home/airflow/.local/lib/python3.8/site-packages/airflow/models/connection.py", line 477, in get_connection_from_secrets
    raise AirflowNotFoundException(f"The conn_id `{conn_id}` isn't defined")
airflow.exceptions.AirflowNotFoundException: The conn_id `postgre_sql_conn` isn't defined
[2023-11-23T01:10:03.824+0000] {processor.py:841} WARNING - No viable dags retrieved from /opt/airflow/dags/pg_read_dag.py
[2023-11-23T01:10:03.842+0000] {processor.py:179} INFO - Processing /opt/airflow/dags/pg_read_dag.py took 0.092 seconds
[2023-11-23T01:10:34.266+0000] {processor.py:157} INFO - Started process (PID=1451) to work on /opt/airflow/dags/pg_read_dag.py
[2023-11-23T01:10:34.268+0000] {processor.py:829} INFO - Processing file /opt/airflow/dags/pg_read_dag.py for tasks to queue
[2023-11-23T01:10:34.270+0000] {logging_mixin.py:151} INFO - [2023-11-23T01:10:34.269+0000] {dagbag.py:536} INFO - Filling up the DagBag from /opt/airflow/dags/pg_read_dag.py
[2023-11-23T01:10:34.357+0000] {logging_mixin.py:151} INFO - [2023-11-23T01:10:34.344+0000] {dagbag.py:346} ERROR - Failed to import: /opt/airflow/dags/pg_read_dag.py
Traceback (most recent call last):
  File "/home/airflow/.local/lib/python3.8/site-packages/airflow/models/dagbag.py", line 342, in parse
    loader.exec_module(new_module)
  File "<frozen importlib._bootstrap_external>", line 843, in exec_module
  File "<frozen importlib._bootstrap>", line 219, in _call_with_frames_removed
  File "/opt/airflow/dags/pg_read_dag.py", line 7, in <module>
    postgre_con = BaseHook.get_connection('postgre_sql_conn')
  File "/home/airflow/.local/lib/python3.8/site-packages/airflow/hooks/base.py", line 72, in get_connection
    conn = Connection.get_connection_from_secrets(conn_id)
  File "/home/airflow/.local/lib/python3.8/site-packages/airflow/models/connection.py", line 477, in get_connection_from_secrets
    raise AirflowNotFoundException(f"The conn_id `{conn_id}` isn't defined")
airflow.exceptions.AirflowNotFoundException: The conn_id `postgre_sql_conn` isn't defined
[2023-11-23T01:10:34.359+0000] {processor.py:841} WARNING - No viable dags retrieved from /opt/airflow/dags/pg_read_dag.py
[2023-11-23T01:10:34.429+0000] {processor.py:179} INFO - Processing /opt/airflow/dags/pg_read_dag.py took 0.168 seconds
[2023-11-23T01:11:04.874+0000] {processor.py:157} INFO - Started process (PID=1468) to work on /opt/airflow/dags/pg_read_dag.py
[2023-11-23T01:11:04.875+0000] {processor.py:829} INFO - Processing file /opt/airflow/dags/pg_read_dag.py for tasks to queue
[2023-11-23T01:11:04.877+0000] {logging_mixin.py:151} INFO - [2023-11-23T01:11:04.876+0000] {dagbag.py:536} INFO - Filling up the DagBag from /opt/airflow/dags/pg_read_dag.py
[2023-11-23T01:11:04.921+0000] {logging_mixin.py:151} INFO - [2023-11-23T01:11:04.911+0000] {dagbag.py:346} ERROR - Failed to import: /opt/airflow/dags/pg_read_dag.py
Traceback (most recent call last):
  File "/home/airflow/.local/lib/python3.8/site-packages/airflow/models/dagbag.py", line 342, in parse
    loader.exec_module(new_module)
  File "<frozen importlib._bootstrap_external>", line 843, in exec_module
  File "<frozen importlib._bootstrap>", line 219, in _call_with_frames_removed
  File "/opt/airflow/dags/pg_read_dag.py", line 7, in <module>
    postgre_con = BaseHook.get_connection('postgre_sql_conn')
  File "/home/airflow/.local/lib/python3.8/site-packages/airflow/hooks/base.py", line 72, in get_connection
    conn = Connection.get_connection_from_secrets(conn_id)
  File "/home/airflow/.local/lib/python3.8/site-packages/airflow/models/connection.py", line 477, in get_connection_from_secrets
    raise AirflowNotFoundException(f"The conn_id `{conn_id}` isn't defined")
airflow.exceptions.AirflowNotFoundException: The conn_id `postgre_sql_conn` isn't defined
[2023-11-23T01:11:04.922+0000] {processor.py:841} WARNING - No viable dags retrieved from /opt/airflow/dags/pg_read_dag.py
[2023-11-23T01:11:04.935+0000] {processor.py:179} INFO - Processing /opt/airflow/dags/pg_read_dag.py took 0.064 seconds
[2023-11-23T01:11:35.418+0000] {processor.py:157} INFO - Started process (PID=1485) to work on /opt/airflow/dags/pg_read_dag.py
[2023-11-23T01:11:35.419+0000] {processor.py:829} INFO - Processing file /opt/airflow/dags/pg_read_dag.py for tasks to queue
[2023-11-23T01:11:35.420+0000] {logging_mixin.py:151} INFO - [2023-11-23T01:11:35.420+0000] {dagbag.py:536} INFO - Filling up the DagBag from /opt/airflow/dags/pg_read_dag.py
[2023-11-23T01:11:35.461+0000] {logging_mixin.py:151} INFO - [2023-11-23T01:11:35.456+0000] {dagbag.py:346} ERROR - Failed to import: /opt/airflow/dags/pg_read_dag.py
Traceback (most recent call last):
  File "/home/airflow/.local/lib/python3.8/site-packages/airflow/models/dagbag.py", line 342, in parse
    loader.exec_module(new_module)
  File "<frozen importlib._bootstrap_external>", line 843, in exec_module
  File "<frozen importlib._bootstrap>", line 219, in _call_with_frames_removed
  File "/opt/airflow/dags/pg_read_dag.py", line 7, in <module>
    postgre_con = BaseHook.get_connection('postgre_sql_conn')
  File "/home/airflow/.local/lib/python3.8/site-packages/airflow/hooks/base.py", line 72, in get_connection
    conn = Connection.get_connection_from_secrets(conn_id)
  File "/home/airflow/.local/lib/python3.8/site-packages/airflow/models/connection.py", line 477, in get_connection_from_secrets
    raise AirflowNotFoundException(f"The conn_id `{conn_id}` isn't defined")
airflow.exceptions.AirflowNotFoundException: The conn_id `postgre_sql_conn` isn't defined
[2023-11-23T01:11:35.462+0000] {processor.py:841} WARNING - No viable dags retrieved from /opt/airflow/dags/pg_read_dag.py
[2023-11-23T01:11:35.473+0000] {processor.py:179} INFO - Processing /opt/airflow/dags/pg_read_dag.py took 0.058 seconds
[2023-11-23T01:12:05.981+0000] {processor.py:157} INFO - Started process (PID=1502) to work on /opt/airflow/dags/pg_read_dag.py
[2023-11-23T01:12:05.984+0000] {processor.py:829} INFO - Processing file /opt/airflow/dags/pg_read_dag.py for tasks to queue
[2023-11-23T01:12:05.987+0000] {logging_mixin.py:151} INFO - [2023-11-23T01:12:05.986+0000] {dagbag.py:536} INFO - Filling up the DagBag from /opt/airflow/dags/pg_read_dag.py
[2023-11-23T01:12:06.070+0000] {logging_mixin.py:151} INFO - [2023-11-23T01:12:06.062+0000] {dagbag.py:346} ERROR - Failed to import: /opt/airflow/dags/pg_read_dag.py
Traceback (most recent call last):
  File "/home/airflow/.local/lib/python3.8/site-packages/airflow/models/dagbag.py", line 342, in parse
    loader.exec_module(new_module)
  File "<frozen importlib._bootstrap_external>", line 843, in exec_module
  File "<frozen importlib._bootstrap>", line 219, in _call_with_frames_removed
  File "/opt/airflow/dags/pg_read_dag.py", line 7, in <module>
    postgre_con = BaseHook.get_connection('postgre_sql_conn')
  File "/home/airflow/.local/lib/python3.8/site-packages/airflow/hooks/base.py", line 72, in get_connection
    conn = Connection.get_connection_from_secrets(conn_id)
  File "/home/airflow/.local/lib/python3.8/site-packages/airflow/models/connection.py", line 477, in get_connection_from_secrets
    raise AirflowNotFoundException(f"The conn_id `{conn_id}` isn't defined")
airflow.exceptions.AirflowNotFoundException: The conn_id `postgre_sql_conn` isn't defined
[2023-11-23T01:12:06.071+0000] {processor.py:841} WARNING - No viable dags retrieved from /opt/airflow/dags/pg_read_dag.py
[2023-11-23T01:12:06.083+0000] {processor.py:179} INFO - Processing /opt/airflow/dags/pg_read_dag.py took 0.114 seconds
[2023-11-23T01:12:36.566+0000] {processor.py:157} INFO - Started process (PID=1519) to work on /opt/airflow/dags/pg_read_dag.py
[2023-11-23T01:12:36.567+0000] {processor.py:829} INFO - Processing file /opt/airflow/dags/pg_read_dag.py for tasks to queue
[2023-11-23T01:12:36.568+0000] {logging_mixin.py:151} INFO - [2023-11-23T01:12:36.568+0000] {dagbag.py:536} INFO - Filling up the DagBag from /opt/airflow/dags/pg_read_dag.py
[2023-11-23T01:12:36.617+0000] {logging_mixin.py:151} INFO - [2023-11-23T01:12:36.612+0000] {dagbag.py:346} ERROR - Failed to import: /opt/airflow/dags/pg_read_dag.py
Traceback (most recent call last):
  File "/home/airflow/.local/lib/python3.8/site-packages/airflow/models/dagbag.py", line 342, in parse
    loader.exec_module(new_module)
  File "<frozen importlib._bootstrap_external>", line 843, in exec_module
  File "<frozen importlib._bootstrap>", line 219, in _call_with_frames_removed
  File "/opt/airflow/dags/pg_read_dag.py", line 7, in <module>
    postgre_con = BaseHook.get_connection('postgre_sql_conn')
  File "/home/airflow/.local/lib/python3.8/site-packages/airflow/hooks/base.py", line 72, in get_connection
    conn = Connection.get_connection_from_secrets(conn_id)
  File "/home/airflow/.local/lib/python3.8/site-packages/airflow/models/connection.py", line 477, in get_connection_from_secrets
    raise AirflowNotFoundException(f"The conn_id `{conn_id}` isn't defined")
airflow.exceptions.AirflowNotFoundException: The conn_id `postgre_sql_conn` isn't defined
[2023-11-23T01:12:36.618+0000] {processor.py:841} WARNING - No viable dags retrieved from /opt/airflow/dags/pg_read_dag.py
[2023-11-23T01:12:36.656+0000] {processor.py:179} INFO - Processing /opt/airflow/dags/pg_read_dag.py took 0.093 seconds
[2023-11-23T01:13:07.153+0000] {processor.py:157} INFO - Started process (PID=1536) to work on /opt/airflow/dags/pg_read_dag.py
[2023-11-23T01:13:07.156+0000] {processor.py:829} INFO - Processing file /opt/airflow/dags/pg_read_dag.py for tasks to queue
[2023-11-23T01:13:07.159+0000] {logging_mixin.py:151} INFO - [2023-11-23T01:13:07.158+0000] {dagbag.py:536} INFO - Filling up the DagBag from /opt/airflow/dags/pg_read_dag.py
[2023-11-23T01:13:07.227+0000] {logging_mixin.py:151} INFO - [2023-11-23T01:13:07.216+0000] {dagbag.py:346} ERROR - Failed to import: /opt/airflow/dags/pg_read_dag.py
Traceback (most recent call last):
  File "/home/airflow/.local/lib/python3.8/site-packages/airflow/models/dagbag.py", line 342, in parse
    loader.exec_module(new_module)
  File "<frozen importlib._bootstrap_external>", line 843, in exec_module
  File "<frozen importlib._bootstrap>", line 219, in _call_with_frames_removed
  File "/opt/airflow/dags/pg_read_dag.py", line 7, in <module>
    postgre_con = BaseHook.get_connection('postgre_sql_conn')
  File "/home/airflow/.local/lib/python3.8/site-packages/airflow/hooks/base.py", line 72, in get_connection
    conn = Connection.get_connection_from_secrets(conn_id)
  File "/home/airflow/.local/lib/python3.8/site-packages/airflow/models/connection.py", line 477, in get_connection_from_secrets
    raise AirflowNotFoundException(f"The conn_id `{conn_id}` isn't defined")
airflow.exceptions.AirflowNotFoundException: The conn_id `postgre_sql_conn` isn't defined
[2023-11-23T01:13:07.228+0000] {processor.py:841} WARNING - No viable dags retrieved from /opt/airflow/dags/pg_read_dag.py
[2023-11-23T01:13:07.248+0000] {processor.py:179} INFO - Processing /opt/airflow/dags/pg_read_dag.py took 0.105 seconds
[2023-11-23T01:13:37.767+0000] {processor.py:157} INFO - Started process (PID=1553) to work on /opt/airflow/dags/pg_read_dag.py
[2023-11-23T01:13:37.770+0000] {processor.py:829} INFO - Processing file /opt/airflow/dags/pg_read_dag.py for tasks to queue
[2023-11-23T01:13:37.773+0000] {logging_mixin.py:151} INFO - [2023-11-23T01:13:37.772+0000] {dagbag.py:536} INFO - Filling up the DagBag from /opt/airflow/dags/pg_read_dag.py
[2023-11-23T01:13:37.865+0000] {logging_mixin.py:151} INFO - [2023-11-23T01:13:37.855+0000] {dagbag.py:346} ERROR - Failed to import: /opt/airflow/dags/pg_read_dag.py
Traceback (most recent call last):
  File "/home/airflow/.local/lib/python3.8/site-packages/airflow/models/dagbag.py", line 342, in parse
    loader.exec_module(new_module)
  File "<frozen importlib._bootstrap_external>", line 843, in exec_module
  File "<frozen importlib._bootstrap>", line 219, in _call_with_frames_removed
  File "/opt/airflow/dags/pg_read_dag.py", line 7, in <module>
    postgre_con = BaseHook.get_connection('postgre_sql_conn')
  File "/home/airflow/.local/lib/python3.8/site-packages/airflow/hooks/base.py", line 72, in get_connection
    conn = Connection.get_connection_from_secrets(conn_id)
  File "/home/airflow/.local/lib/python3.8/site-packages/airflow/models/connection.py", line 477, in get_connection_from_secrets
    raise AirflowNotFoundException(f"The conn_id `{conn_id}` isn't defined")
airflow.exceptions.AirflowNotFoundException: The conn_id `postgre_sql_conn` isn't defined
[2023-11-23T01:13:37.866+0000] {processor.py:841} WARNING - No viable dags retrieved from /opt/airflow/dags/pg_read_dag.py
[2023-11-23T01:13:37.930+0000] {processor.py:179} INFO - Processing /opt/airflow/dags/pg_read_dag.py took 0.170 seconds
[2023-11-23T01:14:08.228+0000] {processor.py:157} INFO - Started process (PID=1570) to work on /opt/airflow/dags/pg_read_dag.py
[2023-11-23T01:14:08.231+0000] {processor.py:829} INFO - Processing file /opt/airflow/dags/pg_read_dag.py for tasks to queue
[2023-11-23T01:14:08.234+0000] {logging_mixin.py:151} INFO - [2023-11-23T01:14:08.233+0000] {dagbag.py:536} INFO - Filling up the DagBag from /opt/airflow/dags/pg_read_dag.py
[2023-11-23T01:14:08.331+0000] {logging_mixin.py:151} INFO - [2023-11-23T01:14:08.319+0000] {dagbag.py:346} ERROR - Failed to import: /opt/airflow/dags/pg_read_dag.py
Traceback (most recent call last):
  File "/home/airflow/.local/lib/python3.8/site-packages/airflow/models/dagbag.py", line 342, in parse
    loader.exec_module(new_module)
  File "<frozen importlib._bootstrap_external>", line 843, in exec_module
  File "<frozen importlib._bootstrap>", line 219, in _call_with_frames_removed
  File "/opt/airflow/dags/pg_read_dag.py", line 7, in <module>
    postgre_con = BaseHook.get_connection('postgre_sql_conn')
  File "/home/airflow/.local/lib/python3.8/site-packages/airflow/hooks/base.py", line 72, in get_connection
    conn = Connection.get_connection_from_secrets(conn_id)
  File "/home/airflow/.local/lib/python3.8/site-packages/airflow/models/connection.py", line 477, in get_connection_from_secrets
    raise AirflowNotFoundException(f"The conn_id `{conn_id}` isn't defined")
airflow.exceptions.AirflowNotFoundException: The conn_id `postgre_sql_conn` isn't defined
[2023-11-23T01:14:08.332+0000] {processor.py:841} WARNING - No viable dags retrieved from /opt/airflow/dags/pg_read_dag.py
[2023-11-23T01:14:08.351+0000] {processor.py:179} INFO - Processing /opt/airflow/dags/pg_read_dag.py took 0.127 seconds
[2023-11-23T01:14:38.824+0000] {processor.py:157} INFO - Started process (PID=1587) to work on /opt/airflow/dags/pg_read_dag.py
[2023-11-23T01:14:38.826+0000] {processor.py:829} INFO - Processing file /opt/airflow/dags/pg_read_dag.py for tasks to queue
[2023-11-23T01:14:38.828+0000] {logging_mixin.py:151} INFO - [2023-11-23T01:14:38.827+0000] {dagbag.py:536} INFO - Filling up the DagBag from /opt/airflow/dags/pg_read_dag.py
[2023-11-23T01:14:38.886+0000] {logging_mixin.py:151} INFO - [2023-11-23T01:14:38.878+0000] {dagbag.py:346} ERROR - Failed to import: /opt/airflow/dags/pg_read_dag.py
Traceback (most recent call last):
  File "/home/airflow/.local/lib/python3.8/site-packages/airflow/models/dagbag.py", line 342, in parse
    loader.exec_module(new_module)
  File "<frozen importlib._bootstrap_external>", line 843, in exec_module
  File "<frozen importlib._bootstrap>", line 219, in _call_with_frames_removed
  File "/opt/airflow/dags/pg_read_dag.py", line 7, in <module>
    postgre_con = BaseHook.get_connection('postgre_sql_conn')
  File "/home/airflow/.local/lib/python3.8/site-packages/airflow/hooks/base.py", line 72, in get_connection
    conn = Connection.get_connection_from_secrets(conn_id)
  File "/home/airflow/.local/lib/python3.8/site-packages/airflow/models/connection.py", line 477, in get_connection_from_secrets
    raise AirflowNotFoundException(f"The conn_id `{conn_id}` isn't defined")
airflow.exceptions.AirflowNotFoundException: The conn_id `postgre_sql_conn` isn't defined
[2023-11-23T01:14:38.887+0000] {processor.py:841} WARNING - No viable dags retrieved from /opt/airflow/dags/pg_read_dag.py
[2023-11-23T01:14:38.898+0000] {processor.py:179} INFO - Processing /opt/airflow/dags/pg_read_dag.py took 0.078 seconds
[2023-11-23T01:15:09.335+0000] {processor.py:157} INFO - Started process (PID=1604) to work on /opt/airflow/dags/pg_read_dag.py
[2023-11-23T01:15:09.337+0000] {processor.py:829} INFO - Processing file /opt/airflow/dags/pg_read_dag.py for tasks to queue
[2023-11-23T01:15:09.338+0000] {logging_mixin.py:151} INFO - [2023-11-23T01:15:09.337+0000] {dagbag.py:536} INFO - Filling up the DagBag from /opt/airflow/dags/pg_read_dag.py
[2023-11-23T01:15:09.377+0000] {logging_mixin.py:151} INFO - [2023-11-23T01:15:09.369+0000] {dagbag.py:346} ERROR - Failed to import: /opt/airflow/dags/pg_read_dag.py
Traceback (most recent call last):
  File "/home/airflow/.local/lib/python3.8/site-packages/airflow/models/dagbag.py", line 342, in parse
    loader.exec_module(new_module)
  File "<frozen importlib._bootstrap_external>", line 843, in exec_module
  File "<frozen importlib._bootstrap>", line 219, in _call_with_frames_removed
  File "/opt/airflow/dags/pg_read_dag.py", line 7, in <module>
    postgre_con = BaseHook.get_connection('postgre_sql_conn')
  File "/home/airflow/.local/lib/python3.8/site-packages/airflow/hooks/base.py", line 72, in get_connection
    conn = Connection.get_connection_from_secrets(conn_id)
  File "/home/airflow/.local/lib/python3.8/site-packages/airflow/models/connection.py", line 477, in get_connection_from_secrets
    raise AirflowNotFoundException(f"The conn_id `{conn_id}` isn't defined")
airflow.exceptions.AirflowNotFoundException: The conn_id `postgre_sql_conn` isn't defined
[2023-11-23T01:15:09.378+0000] {processor.py:841} WARNING - No viable dags retrieved from /opt/airflow/dags/pg_read_dag.py
[2023-11-23T01:15:09.390+0000] {processor.py:179} INFO - Processing /opt/airflow/dags/pg_read_dag.py took 0.058 seconds
[2023-11-23T01:15:39.963+0000] {processor.py:157} INFO - Started process (PID=1621) to work on /opt/airflow/dags/pg_read_dag.py
[2023-11-23T01:15:39.965+0000] {processor.py:829} INFO - Processing file /opt/airflow/dags/pg_read_dag.py for tasks to queue
[2023-11-23T01:15:39.967+0000] {logging_mixin.py:151} INFO - [2023-11-23T01:15:39.966+0000] {dagbag.py:536} INFO - Filling up the DagBag from /opt/airflow/dags/pg_read_dag.py
[2023-11-23T01:15:40.044+0000] {logging_mixin.py:151} INFO - [2023-11-23T01:15:40.031+0000] {dagbag.py:346} ERROR - Failed to import: /opt/airflow/dags/pg_read_dag.py
Traceback (most recent call last):
  File "/home/airflow/.local/lib/python3.8/site-packages/airflow/models/dagbag.py", line 342, in parse
    loader.exec_module(new_module)
  File "<frozen importlib._bootstrap_external>", line 843, in exec_module
  File "<frozen importlib._bootstrap>", line 219, in _call_with_frames_removed
  File "/opt/airflow/dags/pg_read_dag.py", line 7, in <module>
    postgre_con = BaseHook.get_connection('postgre_sql_conn')
  File "/home/airflow/.local/lib/python3.8/site-packages/airflow/hooks/base.py", line 72, in get_connection
    conn = Connection.get_connection_from_secrets(conn_id)
  File "/home/airflow/.local/lib/python3.8/site-packages/airflow/models/connection.py", line 477, in get_connection_from_secrets
    raise AirflowNotFoundException(f"The conn_id `{conn_id}` isn't defined")
airflow.exceptions.AirflowNotFoundException: The conn_id `postgre_sql_conn` isn't defined
[2023-11-23T01:15:40.045+0000] {processor.py:841} WARNING - No viable dags retrieved from /opt/airflow/dags/pg_read_dag.py
[2023-11-23T01:15:40.062+0000] {processor.py:179} INFO - Processing /opt/airflow/dags/pg_read_dag.py took 0.106 seconds
[2023-11-23T01:16:10.575+0000] {processor.py:157} INFO - Started process (PID=1638) to work on /opt/airflow/dags/pg_read_dag.py
[2023-11-23T01:16:10.578+0000] {processor.py:829} INFO - Processing file /opt/airflow/dags/pg_read_dag.py for tasks to queue
[2023-11-23T01:16:10.580+0000] {logging_mixin.py:151} INFO - [2023-11-23T01:16:10.579+0000] {dagbag.py:536} INFO - Filling up the DagBag from /opt/airflow/dags/pg_read_dag.py
[2023-11-23T01:16:10.648+0000] {logging_mixin.py:151} INFO - [2023-11-23T01:16:10.636+0000] {dagbag.py:346} ERROR - Failed to import: /opt/airflow/dags/pg_read_dag.py
Traceback (most recent call last):
  File "/home/airflow/.local/lib/python3.8/site-packages/airflow/models/dagbag.py", line 342, in parse
    loader.exec_module(new_module)
  File "<frozen importlib._bootstrap_external>", line 843, in exec_module
  File "<frozen importlib._bootstrap>", line 219, in _call_with_frames_removed
  File "/opt/airflow/dags/pg_read_dag.py", line 7, in <module>
    postgre_con = BaseHook.get_connection('postgre_sql_conn')
  File "/home/airflow/.local/lib/python3.8/site-packages/airflow/hooks/base.py", line 72, in get_connection
    conn = Connection.get_connection_from_secrets(conn_id)
  File "/home/airflow/.local/lib/python3.8/site-packages/airflow/models/connection.py", line 477, in get_connection_from_secrets
    raise AirflowNotFoundException(f"The conn_id `{conn_id}` isn't defined")
airflow.exceptions.AirflowNotFoundException: The conn_id `postgre_sql_conn` isn't defined
[2023-11-23T01:16:10.650+0000] {processor.py:841} WARNING - No viable dags retrieved from /opt/airflow/dags/pg_read_dag.py
[2023-11-23T01:16:10.670+0000] {processor.py:179} INFO - Processing /opt/airflow/dags/pg_read_dag.py took 0.104 seconds
[2023-11-23T01:16:41.249+0000] {processor.py:157} INFO - Started process (PID=1655) to work on /opt/airflow/dags/pg_read_dag.py
[2023-11-23T01:16:41.252+0000] {processor.py:829} INFO - Processing file /opt/airflow/dags/pg_read_dag.py for tasks to queue
[2023-11-23T01:16:41.255+0000] {logging_mixin.py:151} INFO - [2023-11-23T01:16:41.254+0000] {dagbag.py:536} INFO - Filling up the DagBag from /opt/airflow/dags/pg_read_dag.py
[2023-11-23T01:16:41.349+0000] {logging_mixin.py:151} INFO - [2023-11-23T01:16:41.345+0000] {dagbag.py:346} ERROR - Failed to import: /opt/airflow/dags/pg_read_dag.py
Traceback (most recent call last):
  File "/home/airflow/.local/lib/python3.8/site-packages/airflow/models/dagbag.py", line 342, in parse
    loader.exec_module(new_module)
  File "<frozen importlib._bootstrap_external>", line 843, in exec_module
  File "<frozen importlib._bootstrap>", line 219, in _call_with_frames_removed
  File "/opt/airflow/dags/pg_read_dag.py", line 7, in <module>
    postgre_con = BaseHook.get_connection('postgre_sql_conn')
  File "/home/airflow/.local/lib/python3.8/site-packages/airflow/hooks/base.py", line 72, in get_connection
    conn = Connection.get_connection_from_secrets(conn_id)
  File "/home/airflow/.local/lib/python3.8/site-packages/airflow/models/connection.py", line 477, in get_connection_from_secrets
    raise AirflowNotFoundException(f"The conn_id `{conn_id}` isn't defined")
airflow.exceptions.AirflowNotFoundException: The conn_id `postgre_sql_conn` isn't defined
[2023-11-23T01:16:41.350+0000] {processor.py:841} WARNING - No viable dags retrieved from /opt/airflow/dags/pg_read_dag.py
[2023-11-23T01:16:41.362+0000] {processor.py:179} INFO - Processing /opt/airflow/dags/pg_read_dag.py took 0.122 seconds
[2023-11-23T01:17:11.810+0000] {processor.py:157} INFO - Started process (PID=1672) to work on /opt/airflow/dags/pg_read_dag.py
[2023-11-23T01:17:11.811+0000] {processor.py:829} INFO - Processing file /opt/airflow/dags/pg_read_dag.py for tasks to queue
[2023-11-23T01:17:11.812+0000] {logging_mixin.py:151} INFO - [2023-11-23T01:17:11.812+0000] {dagbag.py:536} INFO - Filling up the DagBag from /opt/airflow/dags/pg_read_dag.py
[2023-11-23T01:17:11.853+0000] {logging_mixin.py:151} INFO - [2023-11-23T01:17:11.847+0000] {dagbag.py:346} ERROR - Failed to import: /opt/airflow/dags/pg_read_dag.py
Traceback (most recent call last):
  File "/home/airflow/.local/lib/python3.8/site-packages/airflow/models/dagbag.py", line 342, in parse
    loader.exec_module(new_module)
  File "<frozen importlib._bootstrap_external>", line 843, in exec_module
  File "<frozen importlib._bootstrap>", line 219, in _call_with_frames_removed
  File "/opt/airflow/dags/pg_read_dag.py", line 7, in <module>
    postgre_con = BaseHook.get_connection('postgre_sql_conn')
  File "/home/airflow/.local/lib/python3.8/site-packages/airflow/hooks/base.py", line 72, in get_connection
    conn = Connection.get_connection_from_secrets(conn_id)
  File "/home/airflow/.local/lib/python3.8/site-packages/airflow/models/connection.py", line 477, in get_connection_from_secrets
    raise AirflowNotFoundException(f"The conn_id `{conn_id}` isn't defined")
airflow.exceptions.AirflowNotFoundException: The conn_id `postgre_sql_conn` isn't defined
[2023-11-23T01:17:11.854+0000] {processor.py:841} WARNING - No viable dags retrieved from /opt/airflow/dags/pg_read_dag.py
[2023-11-23T01:17:11.865+0000] {processor.py:179} INFO - Processing /opt/airflow/dags/pg_read_dag.py took 0.058 seconds
