[2023-11-26T12:34:37.027+0000] {taskinstance.py:1159} INFO - Dependencies all met for dep_context=non-requeueable deps ti=<TaskInstance: dag_pg_insert.firs_task manual__2023-11-26T12:34:35.995924+00:00 [queued]>
[2023-11-26T12:34:37.045+0000] {taskinstance.py:1159} INFO - Dependencies all met for dep_context=requeueable deps ti=<TaskInstance: dag_pg_insert.firs_task manual__2023-11-26T12:34:35.995924+00:00 [queued]>
[2023-11-26T12:34:37.046+0000] {taskinstance.py:1361} INFO - Starting attempt 1 of 4
[2023-11-26T12:34:37.127+0000] {taskinstance.py:1382} INFO - Executing <Task(BashOperator): firs_task> on 2023-11-26 12:34:35.995924+00:00
[2023-11-26T12:34:37.136+0000] {standard_task_runner.py:57} INFO - Started process 1082 to run task
[2023-11-26T12:34:37.145+0000] {standard_task_runner.py:84} INFO - Running: ['***', 'tasks', 'run', 'dag_pg_insert', 'firs_task', 'manual__2023-11-26T12:34:35.995924+00:00', '--job-id', '1869', '--raw', '--subdir', 'DAGS_FOLDER/pg_insert_dag.py', '--cfg-path', '/tmp/tmpvvniml7a']
[2023-11-26T12:34:37.154+0000] {standard_task_runner.py:85} INFO - Job 1869: Subtask firs_task
[2023-11-26T12:34:37.278+0000] {task_command.py:416} INFO - Running <TaskInstance: dag_pg_insert.firs_task manual__2023-11-26T12:34:35.995924+00:00 [running]> on host 3498adef4c60
[2023-11-26T12:34:37.465+0000] {taskinstance.py:1662} INFO - Exporting env vars: AIRFLOW_CTX_DAG_EMAIL='butin_0404@mail.com' AIRFLOW_CTX_DAG_OWNER='big_data' AIRFLOW_CTX_DAG_ID='dag_pg_insert' AIRFLOW_CTX_TASK_ID='firs_task' AIRFLOW_CTX_EXECUTION_DATE='2023-11-26T12:34:35.995924+00:00' AIRFLOW_CTX_TRY_NUMBER='1' AIRFLOW_CTX_DAG_RUN_ID='manual__2023-11-26T12:34:35.995924+00:00'
[2023-11-26T12:34:37.468+0000] {subprocess.py:63} INFO - Tmp dir root location: /tmp
[2023-11-26T12:34:37.470+0000] {subprocess.py:75} INFO - Running command: ['/bin/bash', '-c', 'python3 /opt/***/dags/pg_read.py 127.0.0.1 *** *** 5433']
[2023-11-26T12:34:37.487+0000] {subprocess.py:86} INFO - Output:
[2023-11-26T12:34:38.720+0000] {subprocess.py:93} INFO - 127.0.0.1 *** *** 5433
[2023-11-26T12:34:38.733+0000] {subprocess.py:93} INFO - Traceback (most recent call last):
[2023-11-26T12:34:38.733+0000] {subprocess.py:93} INFO -   File "/home/***/.local/lib/python3.8/site-packages/sqlalchemy/engine/base.py", line 3371, in _wrap_pool_connect
[2023-11-26T12:34:38.734+0000] {subprocess.py:93} INFO -     return fn()
[2023-11-26T12:34:38.735+0000] {subprocess.py:93} INFO -   File "/home/***/.local/lib/python3.8/site-packages/sqlalchemy/pool/base.py", line 327, in connect
[2023-11-26T12:34:38.736+0000] {subprocess.py:93} INFO -     return _ConnectionFairy._checkout(self)
[2023-11-26T12:34:38.737+0000] {subprocess.py:93} INFO -   File "/home/***/.local/lib/python3.8/site-packages/sqlalchemy/pool/base.py", line 894, in _checkout
[2023-11-26T12:34:38.737+0000] {subprocess.py:93} INFO -     fairy = _ConnectionRecord.checkout(pool)
[2023-11-26T12:34:38.738+0000] {subprocess.py:93} INFO -   File "/home/***/.local/lib/python3.8/site-packages/sqlalchemy/pool/base.py", line 493, in checkout
[2023-11-26T12:34:38.739+0000] {subprocess.py:93} INFO -     rec = pool._do_get()
[2023-11-26T12:34:38.739+0000] {subprocess.py:93} INFO -   File "/home/***/.local/lib/python3.8/site-packages/sqlalchemy/pool/impl.py", line 146, in _do_get
[2023-11-26T12:34:38.740+0000] {subprocess.py:93} INFO -     self._dec_overflow()
[2023-11-26T12:34:38.741+0000] {subprocess.py:93} INFO -   File "/home/***/.local/lib/python3.8/site-packages/sqlalchemy/util/langhelpers.py", line 70, in __exit__
[2023-11-26T12:34:38.741+0000] {subprocess.py:93} INFO -     compat.raise_(
[2023-11-26T12:34:38.742+0000] {subprocess.py:93} INFO -   File "/home/***/.local/lib/python3.8/site-packages/sqlalchemy/util/compat.py", line 211, in raise_
[2023-11-26T12:34:38.743+0000] {subprocess.py:93} INFO -     raise exception
[2023-11-26T12:34:38.743+0000] {subprocess.py:93} INFO -   File "/home/***/.local/lib/python3.8/site-packages/sqlalchemy/pool/impl.py", line 143, in _do_get
[2023-11-26T12:34:38.744+0000] {subprocess.py:93} INFO -     return self._create_connection()
[2023-11-26T12:34:38.745+0000] {subprocess.py:93} INFO -   File "/home/***/.local/lib/python3.8/site-packages/sqlalchemy/pool/base.py", line 273, in _create_connection
[2023-11-26T12:34:38.745+0000] {subprocess.py:93} INFO -     return _ConnectionRecord(self)
[2023-11-26T12:34:38.746+0000] {subprocess.py:93} INFO -   File "/home/***/.local/lib/python3.8/site-packages/sqlalchemy/pool/base.py", line 388, in __init__
[2023-11-26T12:34:38.746+0000] {subprocess.py:93} INFO -     self.__connect()
[2023-11-26T12:34:38.747+0000] {subprocess.py:93} INFO -   File "/home/***/.local/lib/python3.8/site-packages/sqlalchemy/pool/base.py", line 691, in __connect
[2023-11-26T12:34:38.748+0000] {subprocess.py:93} INFO -     pool.logger.debug("Error on connect(): %s", e)
[2023-11-26T12:34:38.749+0000] {subprocess.py:93} INFO -   File "/home/***/.local/lib/python3.8/site-packages/sqlalchemy/util/langhelpers.py", line 70, in __exit__
[2023-11-26T12:34:38.750+0000] {subprocess.py:93} INFO -     compat.raise_(
[2023-11-26T12:34:38.751+0000] {subprocess.py:93} INFO -   File "/home/***/.local/lib/python3.8/site-packages/sqlalchemy/util/compat.py", line 211, in raise_
[2023-11-26T12:34:38.752+0000] {subprocess.py:93} INFO -     raise exception
[2023-11-26T12:34:38.752+0000] {subprocess.py:93} INFO -   File "/home/***/.local/lib/python3.8/site-packages/sqlalchemy/pool/base.py", line 686, in __connect
[2023-11-26T12:34:38.752+0000] {subprocess.py:93} INFO -     self.dbapi_connection = connection = pool._invoke_creator(self)
[2023-11-26T12:34:38.753+0000] {subprocess.py:93} INFO -   File "/home/***/.local/lib/python3.8/site-packages/sqlalchemy/engine/create.py", line 574, in connect
[2023-11-26T12:34:38.754+0000] {subprocess.py:93} INFO -     return dialect.connect(*cargs, **cparams)
[2023-11-26T12:34:38.754+0000] {subprocess.py:93} INFO -   File "/home/***/.local/lib/python3.8/site-packages/sqlalchemy/engine/default.py", line 598, in connect
[2023-11-26T12:34:38.755+0000] {subprocess.py:93} INFO -     return self.dbapi.connect(*cargs, **cparams)
[2023-11-26T12:34:38.756+0000] {subprocess.py:93} INFO -   File "/home/***/.local/lib/python3.8/site-packages/psycopg2/__init__.py", line 122, in connect
[2023-11-26T12:34:38.757+0000] {subprocess.py:93} INFO -     conn = _connect(dsn, connection_factory=connection_factory, **kwasync)
[2023-11-26T12:34:38.757+0000] {subprocess.py:93} INFO - psycopg2.OperationalError: connection to server at "127.0.0.1", port 5432 failed: Connection refused
[2023-11-26T12:34:38.758+0000] {subprocess.py:93} INFO - 	Is the server running on that host and accepting TCP/IP connections?
[2023-11-26T12:34:38.758+0000] {subprocess.py:93} INFO - 
[2023-11-26T12:34:38.759+0000] {subprocess.py:93} INFO - 
[2023-11-26T12:34:38.759+0000] {subprocess.py:93} INFO - The above exception was the direct cause of the following exception:
[2023-11-26T12:34:38.760+0000] {subprocess.py:93} INFO - 
[2023-11-26T12:34:38.760+0000] {subprocess.py:93} INFO - Traceback (most recent call last):
[2023-11-26T12:34:38.761+0000] {subprocess.py:93} INFO -   File "/opt/***/dags/pg_read.py", line 26, in <module>
[2023-11-26T12:34:38.761+0000] {subprocess.py:93} INFO -     df = pd.read_sql(sql, engine)
[2023-11-26T12:34:38.762+0000] {subprocess.py:93} INFO -   File "/home/***/.local/lib/python3.8/site-packages/pandas/io/sql.py", line 633, in read_sql
[2023-11-26T12:34:38.762+0000] {subprocess.py:93} INFO -     with pandasSQL_builder(con) as pandas_sql:
[2023-11-26T12:34:38.763+0000] {subprocess.py:93} INFO -   File "/home/***/.local/lib/python3.8/site-packages/pandas/io/sql.py", line 832, in pandasSQL_builder
[2023-11-26T12:34:38.764+0000] {subprocess.py:93} INFO -     return SQLDatabase(con, schema, need_transaction)
[2023-11-26T12:34:38.764+0000] {subprocess.py:93} INFO -   File "/home/***/.local/lib/python3.8/site-packages/pandas/io/sql.py", line 1539, in __init__
[2023-11-26T12:34:38.765+0000] {subprocess.py:93} INFO -     con = self.exit_stack.enter_context(con.connect())
[2023-11-26T12:34:38.765+0000] {subprocess.py:93} INFO -   File "/home/***/.local/lib/python3.8/site-packages/sqlalchemy/engine/base.py", line 3325, in connect
[2023-11-26T12:34:38.766+0000] {subprocess.py:93} INFO -     return self._connection_cls(self, close_with_result=close_with_result)
[2023-11-26T12:34:38.767+0000] {subprocess.py:93} INFO -   File "/home/***/.local/lib/python3.8/site-packages/sqlalchemy/engine/base.py", line 96, in __init__
[2023-11-26T12:34:38.768+0000] {subprocess.py:93} INFO -     else engine.raw_connection()
[2023-11-26T12:34:38.768+0000] {subprocess.py:93} INFO -   File "/home/***/.local/lib/python3.8/site-packages/sqlalchemy/engine/base.py", line 3404, in raw_connection
[2023-11-26T12:34:38.769+0000] {subprocess.py:93} INFO -     return self._wrap_pool_connect(self.pool.connect, _connection)
[2023-11-26T12:34:38.770+0000] {subprocess.py:93} INFO -   File "/home/***/.local/lib/python3.8/site-packages/sqlalchemy/engine/base.py", line 3374, in _wrap_pool_connect
[2023-11-26T12:34:38.771+0000] {subprocess.py:93} INFO -     Connection._handle_dbapi_exception_noconnection(
[2023-11-26T12:34:38.772+0000] {subprocess.py:93} INFO -   File "/home/***/.local/lib/python3.8/site-packages/sqlalchemy/engine/base.py", line 2208, in _handle_dbapi_exception_noconnection
[2023-11-26T12:34:38.772+0000] {subprocess.py:93} INFO -     util.raise_(
[2023-11-26T12:34:38.773+0000] {subprocess.py:93} INFO -   File "/home/***/.local/lib/python3.8/site-packages/sqlalchemy/util/compat.py", line 211, in raise_
[2023-11-26T12:34:38.774+0000] {subprocess.py:93} INFO -     raise exception
[2023-11-26T12:34:38.775+0000] {subprocess.py:93} INFO -   File "/home/***/.local/lib/python3.8/site-packages/sqlalchemy/engine/base.py", line 3371, in _wrap_pool_connect
[2023-11-26T12:34:38.775+0000] {subprocess.py:93} INFO -     return fn()
[2023-11-26T12:34:38.776+0000] {subprocess.py:93} INFO -   File "/home/***/.local/lib/python3.8/site-packages/sqlalchemy/pool/base.py", line 327, in connect
[2023-11-26T12:34:38.776+0000] {subprocess.py:93} INFO -     return _ConnectionFairy._checkout(self)
[2023-11-26T12:34:38.777+0000] {subprocess.py:93} INFO -   File "/home/***/.local/lib/python3.8/site-packages/sqlalchemy/pool/base.py", line 894, in _checkout
[2023-11-26T12:34:38.778+0000] {subprocess.py:93} INFO -     fairy = _ConnectionRecord.checkout(pool)
[2023-11-26T12:34:38.778+0000] {subprocess.py:93} INFO -   File "/home/***/.local/lib/python3.8/site-packages/sqlalchemy/pool/base.py", line 493, in checkout
[2023-11-26T12:34:38.779+0000] {subprocess.py:93} INFO -     rec = pool._do_get()
[2023-11-26T12:34:38.780+0000] {subprocess.py:93} INFO -   File "/home/***/.local/lib/python3.8/site-packages/sqlalchemy/pool/impl.py", line 146, in _do_get
[2023-11-26T12:34:38.780+0000] {subprocess.py:93} INFO -     self._dec_overflow()
[2023-11-26T12:34:38.781+0000] {subprocess.py:93} INFO -   File "/home/***/.local/lib/python3.8/site-packages/sqlalchemy/util/langhelpers.py", line 70, in __exit__
[2023-11-26T12:34:38.782+0000] {subprocess.py:93} INFO -     compat.raise_(
[2023-11-26T12:34:38.784+0000] {subprocess.py:93} INFO -   File "/home/***/.local/lib/python3.8/site-packages/sqlalchemy/util/compat.py", line 211, in raise_
[2023-11-26T12:34:38.785+0000] {subprocess.py:93} INFO -     raise exception
[2023-11-26T12:34:38.786+0000] {subprocess.py:93} INFO -   File "/home/***/.local/lib/python3.8/site-packages/sqlalchemy/pool/impl.py", line 143, in _do_get
[2023-11-26T12:34:38.787+0000] {subprocess.py:93} INFO -     return self._create_connection()
[2023-11-26T12:34:38.788+0000] {subprocess.py:93} INFO -   File "/home/***/.local/lib/python3.8/site-packages/sqlalchemy/pool/base.py", line 273, in _create_connection
[2023-11-26T12:34:38.788+0000] {subprocess.py:93} INFO -     return _ConnectionRecord(self)
[2023-11-26T12:34:38.789+0000] {subprocess.py:93} INFO -   File "/home/***/.local/lib/python3.8/site-packages/sqlalchemy/pool/base.py", line 388, in __init__
[2023-11-26T12:34:38.790+0000] {subprocess.py:93} INFO -     self.__connect()
[2023-11-26T12:34:38.791+0000] {subprocess.py:93} INFO -   File "/home/***/.local/lib/python3.8/site-packages/sqlalchemy/pool/base.py", line 691, in __connect
[2023-11-26T12:34:38.791+0000] {subprocess.py:93} INFO -     pool.logger.debug("Error on connect(): %s", e)
[2023-11-26T12:34:38.792+0000] {subprocess.py:93} INFO -   File "/home/***/.local/lib/python3.8/site-packages/sqlalchemy/util/langhelpers.py", line 70, in __exit__
[2023-11-26T12:34:38.793+0000] {subprocess.py:93} INFO -     compat.raise_(
[2023-11-26T12:34:38.794+0000] {subprocess.py:93} INFO -   File "/home/***/.local/lib/python3.8/site-packages/sqlalchemy/util/compat.py", line 211, in raise_
[2023-11-26T12:34:38.794+0000] {subprocess.py:93} INFO -     raise exception
[2023-11-26T12:34:38.795+0000] {subprocess.py:93} INFO -   File "/home/***/.local/lib/python3.8/site-packages/sqlalchemy/pool/base.py", line 686, in __connect
[2023-11-26T12:34:38.796+0000] {subprocess.py:93} INFO -     self.dbapi_connection = connection = pool._invoke_creator(self)
[2023-11-26T12:34:38.796+0000] {subprocess.py:93} INFO -   File "/home/***/.local/lib/python3.8/site-packages/sqlalchemy/engine/create.py", line 574, in connect
[2023-11-26T12:34:38.797+0000] {subprocess.py:93} INFO -     return dialect.connect(*cargs, **cparams)
[2023-11-26T12:34:38.798+0000] {subprocess.py:93} INFO -   File "/home/***/.local/lib/python3.8/site-packages/sqlalchemy/engine/default.py", line 598, in connect
[2023-11-26T12:34:38.798+0000] {subprocess.py:93} INFO -     return self.dbapi.connect(*cargs, **cparams)
[2023-11-26T12:34:38.799+0000] {subprocess.py:93} INFO -   File "/home/***/.local/lib/python3.8/site-packages/psycopg2/__init__.py", line 122, in connect
[2023-11-26T12:34:38.799+0000] {subprocess.py:93} INFO -     conn = _connect(dsn, connection_factory=connection_factory, **kwasync)
[2023-11-26T12:34:38.800+0000] {subprocess.py:93} INFO - sqlalchemy.exc.OperationalError: (psycopg2.OperationalError) connection to server at "127.0.0.1", port 5432 failed: Connection refused
[2023-11-26T12:34:38.800+0000] {subprocess.py:93} INFO - 	Is the server running on that host and accepting TCP/IP connections?
[2023-11-26T12:34:38.801+0000] {subprocess.py:93} INFO - 
[2023-11-26T12:34:38.802+0000] {subprocess.py:93} INFO - (Background on this error at: https://sqlalche.me/e/14/e3q8)
[2023-11-26T12:34:38.859+0000] {subprocess.py:97} INFO - Command exited with return code 1
[2023-11-26T12:34:38.902+0000] {taskinstance.py:1937} ERROR - Task failed with exception
Traceback (most recent call last):
  File "/home/airflow/.local/lib/python3.8/site-packages/airflow/operators/bash.py", line 210, in execute
    raise AirflowException(
airflow.exceptions.AirflowException: Bash command failed. The command returned a non-zero exit code 1.
[2023-11-26T12:34:38.908+0000] {taskinstance.py:1400} INFO - Marking task as UP_FOR_RETRY. dag_id=dag_pg_insert, task_id=firs_task, execution_date=20231126T123435, start_date=20231126T123437, end_date=20231126T123438
[2023-11-26T12:34:38.931+0000] {standard_task_runner.py:104} ERROR - Failed to execute job 1869 for task firs_task (Bash command failed. The command returned a non-zero exit code 1.; 1082)
[2023-11-26T12:34:38.968+0000] {local_task_job_runner.py:228} INFO - Task exited with return code 1
[2023-11-26T12:34:38.994+0000] {taskinstance.py:2778} INFO - 0 downstream tasks scheduled from follow-on schedule check
